Workbook

Sheet Start Here
B1: JOHNNY'S EDGE
B2: Personal Finance Operating System
B3: ="Built 11 Aug 2026 · Last structural update "&TEXT(TODAY(),"dd mmm yyyy") -> Built 11 Aug 2026 · Last structural update 26 Aug 2026
B5: Every number on every sheet is a live formula. Update a balance on Accounts, add a row on Transactions, or change an assumption on Settings — everything downstream recalculates. Nothing here is typed twice.
B8: Sheet | C8: What it's for
B9: Command Center | C9: Open this first, every day. Cash position, this month, what you may spend, the gap, upcoming bills, live alerts.
B10: Today's Brief | C10: The same picture in plain English — read it out loud to yourself in 30 seconds.
B11: Cash Calendar | C11: Week by week to the rent cheque. Shows exactly which week gets tight.
B12: Goals & Future Planning | C12: NEW — UNTOLD Dubai, the couple's trip, and the January rent renewal, with savings targets that never outrank the rent gap.
B13: Weekly Check-In | C13: NEW — spending shown by the week and month, not the day. On-track/over/watch status, plus a rolling 12-week history.
B14: Family & Future Security | C14: NEW — a staged plan for a possible pregnancy, a family-sized emergency fund, and a home, with researched real costs and an honest reality check on timing.
B15: Settings | C15: Every assumption lives here — salary, rent, buffers, thresholds. Change nothing anywhere else.
B16: Accounts | C16: Every account, current balance, what's reserved, what's genuinely spendable.
B17: Account History | C17: NEW — a running log of every account's balance over time, with a trend chart.
B18: Transactions | C18: The master ledger. Add a row here for every expense or income — everything else derives from it.
B19: Bills & Commitments | C19: Every bill and expected inflow, sorted by due date, with real billing-cycle rules.
... B29: Archive - Original | C29: Your original workbook, exactly as uploaded, untouched.
A31: DAILY ROUTINE · under two minutes
B33: 1. | C33: Open Command Center. Check the status colour and read the alerts.
B34: 2. | C34: Update any account balance that's changed on the Accounts sheet.
B35: 3. | C35: Add today's spending to Transactions — five fields, everything else fills itself.
B36: 4. | C36: Once a week: open Cash Calendar and check nothing has gone red.

Sheet MASTER PLAN
B1: THE MASTER PLAN
B2: ="Everything in one place · "&TEXT(TODAY(),"dd mmmm yyyy") -> Everything in one place · 26 August 2026
B3: Cash, rent, debt, investments, family and goals — sequenced. Nothing below jumps the queue.
A5: WHERE YOU STAND TODAY
B6: Measure | C6: Value | F6: Note
B7: Liquid cash (all AED accounts) | C7: =Settings!$B$60 -> 6105.17 | F7: Every account you can touch
B8: Protected (rent vault + emergency) | C8: =Settings!$B$61 -> 5948.37 | F8: Committed — not spending money
B9: Genuinely spendable | C9: =Settings!$B$62 -> 156.8 | F9: What has to last to 26 August
B10: Investments (MF + Amana + Binance) | C10: =Settings!$B$114 -> 12805.332 | F10: Not liquid, not for the rent gap
B11: TOTAL ASSETS | C11: =Settings!$B$115 -> 18910.502 | D11: Net worth after Tabby | E11: =Settings!$B$118 -> 16223.142 | F11: Everything you own, tracked. This line does not net off what you owe.
B12: Status | C12: =Settings!$B$109 -> CRITICAL | F12: Driven by the rent gap, not by net worth
A14: STAGE 1 · NOW → 21 OCTOBER · close the rent gap. Nothing else matters until this is done.
B15: Item | C15: Value | D15: Deadline | F15: How
B16: Rent cheque due | C16: =Settings!$B$19 -> 11750 | D16: 46317 | F16: Cheque clears — must be funded by the 21st
B17: Already vaulted | C17: ='Rent Vault'!$B$11 -> 5940.7 | F17: FAB 4002
B18: Still to fund | C18: ='Rent Vault'!$B$12 -> 5809.3 | D18: 46316 | F18: What the vault still needs
B19: SHORTFALL after all income and bills | C19: =Settings!$B$81 -> 3091.03 | D19: 46316 | F19: The real number — income must cover this
B20: Earn per week | C20: =Settings!$B$83 -> 386.37875 | F20: Every week from now. Log it as it lands.
B21: Daily spending cap to 26 Aug | C21: =Settings!$B$62/14 -> 11.2 | F21: What's left divided by days to payday
B22: Survival floor | C22: =Settings!$B$15 -> 15 | F22: Your cap sits BELOW this — the gap closes through income, not cuts
A24: STAGE 2 · OCT → MID 2027 · rebuild the floor beneath you
B25: Item | C25: Target | D25: Now | E25: Gap | F25: Why it comes first
B26: Safety buffer | C26: =Settings!$B$14 -> 250 | D26: =MIN(Settings!$B$62,Settings!$B$14) -> 156.8 | E26: =MAX($C26-$D26,0) -> 93.2 | F26: One month of breathing room
B27: Emergency fund | C27: ='Family & Future Security'!$B$18 -> 21966 | D27: =Accounts!$D$9 -> 7.67 | E27: =MAX($C27-$D27,0) -> 21958.33 | F27: Six months of essentials. Single income, family coming — this is the real insurance.
B28: Tabby cleared | C28: =Settings!$B$32 -> 2687.36 | D28: =0 -> 0 | E28: =MAX($C28-$D28,0) -> 2687.36 | F28: Once paid, AED 1,314.50/month returns to you permanently
A30: STAGE 3 · FAMILY · start the insurance check now, the saving after Stage 2
B31: Item | C31: Amount | D31: When | F31: Note
B32: Maternity provision | C32: ='Family & Future Security'!$B$32 -> 11000 | F32: Her EBP covers most of it — this is the gap plus newborn essentials
B33: → contingency for scans and extras | C33: ='Family & Future Security'!$B$30 -> 3000 | F33: Editable on the Family sheet
B34: → newborn first year | C34: =Settings!$B$149 -> 8000 | F34: Crib, car seat, paediatrician — insurance covers none of it
B35: CONFIRM WITH HR | C35: — | F35: Five-minute call: is maternity excluded on the Basic tier? Do this regardless of timing.
A37: STAGE 4 · INVESTMENTS · already running — protect it, then accelerate
B38: Path | C38: Timeline to ₹1 crore | D38: Monthly cost | F38: Trade-off
B39: Keep SIP flat (₹12,000/mo) | C39: 13.4 years | D39: ₹12,000 | F39: No change. Slowest, but survivable today.
B40: 10% annual step-up | C40: 11.8 years | D40: Grows to ₹28,297 by yr 10 | F40: Costs more every year. Needs real income growth.
B41: Step-up + restart Motilal ₹6k for 5 yrs | C41: 10.75 years | D41: Peaks ~₹34,000/mo in yr 5 | F41: Fastest realistic path. Motilal is your best performer at 23.81%.
B42: Step-up + Motilal forever | C42: 10.4 years | D42: Same, ongoing | F42: Only 4 months faster than stopping at 5 years — not worth the extra commitment.
B43: 7 years is not achievable | C43: — | F43: Would need ~₹55,000/month, roughly 4.5× your salary. The lever that moves this is income growth, not fund selection.
B44: Current portfolio | C44: =Settings!$B$114 -> 12805.332 | F44: MF ₹245,086 + Amana AED 3,176 + Binance AED 192. Nippon is 95% of the MF side — concentrated in one fund house.
A46: STAGE 5 · GOALS & HOME · funded only after Stages 1–3
...

Sheet Command Center
A1: JOHNNY'S EDGE
A2: ="Financial Command Center · "&TEXT(Settings!$B$9,"dddd, dd mmmm yyyy")&" · "&Settings!$B$66&" days until income" -> Financial Command Center · Wednesday, 26 August 2026 · 31 days until income
A4: =Settings!$B$109&" · HEALTH SCORE "&TEXT(Settings!$B$108,"0")&"/100"&CHAR(10)&IF(Settings!$B$72<0,"After protecting rent and every confirmed commitment you are short by AED "&TEXT(Settings!$B$81,"#,##0.00")&" to reach 21 October. Nothing is safe to spend beyond AED "&TEXT(Settings!$B$75,"#,##0.00")&" a day.","After protecting rent and every confirmed commitment you have AED "&TEXT(Settings!$B$72,"#,##0.00")&" for "&Settings!$B$73&" days — about AED "&TEXT(Settings!$B$75,"#,##0.00")&" a day.") -> CRITICAL · HEALTH SCORE 18/100 After protecting rent and every confirmed commitment you are short by AED 3,091.03 to reach 21 October. Nothing is safe to spend beyond AED 0.00 a day.
A7: CASH POSITION
A8: TOTAL LIQUID CASH | D8: PROTECTED / RESERVED | G8: TRUE SPENDABLE CASH | J8: TOTAL ACCESSIBLE ASSETS
A9: =Settings!$B$60 -> 6105.17 | D9: =Settings!$B$61 -> 5948.37 | G9: =Settings!$B$62 -> 156.8 | J9: =Settings!$B$115 -> 18910.502
A10: All AED accounts | D10: Rent vault + emergency | G10: Before upcoming bills | J10: Cash + investments
A11: EMERGENCY FUND | D11: INVESTMENTS (AED) | G11: BNPL EXPOSURE | J11: RENT FUNDED
A12: =Settings!$B$98 -> 7.67 | D12: =Settings!$B$96+Settings!$B$110+Settings!$B$113 -> 12805.332 | G12: =Settings!$B$101 -> 2687.36 | J12: =Settings!$B$100 -> 0.50559149
A13: ="Target AED "&TEXT(Settings!$B$23,"#,##0")&" · "&TEXT(Settings!$B$99,"0.0%") -> Target AED 1,000 · 0.8% | D13: ="MF "&TEXT(Settings!$B$96,"#,##0")&" + Amana "&TEXT(Settings!$B$110,"#,##0")&" + Binance "&TEXT(Settings!$B$113,"#,##0") -> MF 9,437 + Amana 3,176 + Binance 192 | G13: Tabby — card frozen | J13: ="AED "&TEXT(Settings!$B$70,"#,##0.00")&" still to fund" -> AED 5,809.30 still to fund
A15: THIS MONTH
A16: INCOME RECEIVED | D16: SPENT THIS MONTH | G16: HOUSEHOLD | J16: PERSONAL / LIFESTYLE
A17: =Settings!$B$85 -> 11466.7 | D17: =Settings!$B$86 -> 7587.65 | G17: =Settings!$B$87 -> 6028.4 | J17: =Settings!$B$88 -> 1559.25
A18: Banked only | D18: ="Avg AED "&TEXT(Settings!$B$90,"#,##0.00")&"/day" -> Avg AED 119.99/day | G18: Essential home costs | J18: Discretionary
A19: REMAINING OBLIGATIONS | D19: EXPECTED INFLOWS | G19: PROJECTED MONTH-END CASH | J19: DAYS UNTIL INCOME
A20: =Settings!$B$92 -> 0 | D20: =Settings!$B$93 -> 0 | G20: =Settings!$B$94 -> -443.15962 | J20: =Settings!$B$66 -> 31
A21: Bills left this month | D21: Not yet banked | G21: At current burn rate | J21: ="Payday "&TEXT(Settings!$B$12,"dd mmm") -> Payday 26 Sep
A23: WHAT YOU MAY ACTUALLY SPEND
A24: SURVIVAL / WEEK | D24: SAFE / WEEK | G24: COMFORTABLE / WEEK | J24: WEEKEND ALLOWANCE
A25: =Settings!$B$76*7 -> -332.05516 | D25: =Settings!$B$75*7 -> 0 | G25: =Settings!$B$77*7 -> 0 | J25: =Settings!$B$78 -> 0
A26: ="AED "&TEXT(Settings!$B$76,"#,##0.00")&"/day" -> AED -47.44/day | D26: ="AED "&TEXT(Settings!$B$75,"#,##0.00")&"/day · the binding limit" -> AED 0.00/day · the binding limit | G26: Zero unless finances allow | J26: Safe daily x weekend length
A28: THE GAP
A29: FINANCIAL GAP | D29: GAP WITHOUT BUFFER | G29: EXTRA INCOME / DAY | J29: EXTRA INCOME / WEEK
A30: =Settings!$B$81 -> 3091.03 | D30: =Settings!$B$80 -> 2841.03 | G30: =Settings!$B$82 -> 55.196964 | J30: =Settings!$B$83 -> 386.37875
A31: To 21 Oct, buffer intact | D31: If you sacrifice the buffer | G31: To close the gap | J31: Weekly earning target
A33: UPCOMING OBLIGATIONS · next payments, soonest first
A34: Payment | D34: Due date | F34: Amount | G34: Pay from | I34: Certainty | J34: Status | L34: Days left
A35: =IF(SMALL('Bills & Commitments'!$S$7:$S$80,1)>=99999,"",IFERROR(INDEX('Bills & Commitments'!$B$7:$B$80,MATCH(SMALL('Bills & Commitments'!$S$7:$S$80,1),'Bills & Commitments'!$S$7:$S$80,0)),"")) -> Nippon SIP — September | D35: =IF(SMALL('Bills & Commitments'!$S$7:$S$80,1)>=99999,"",IFERROR(INDEX('Bills & Commitments'!$A$7:$A$80,MATCH(SMALL('Bills & Commitments'!$S$7:$S$80,1),'Bills & Commitments'!$S$7:$S$80,0)),"")) -> 46275 | F35: =IF(SMALL('Bills & Commitments'!$S$7:$S$80,1)>=99999,"",IFERROR(INDEX('Bills & Commitments'!$G$7:$G$80,MATCH(SMALL('Bills & Commitments'!$S$7:$S$80,1),'Bills & Commitments'!$S$7:$S$80,0)),"")) -> 462.4 | G35: =IF(SMALL('Bills & Commitments'!$S$7:$S$80,1)>=99999,"",IFERROR(INDEX('Bills & Commitments'!$K$7:$K$80,MATCH(SMALL('Bills & Commitments'!$S$7:$S$80,1),'Bills & Commitments'!$S$7:$S$80,0)),"")) -> ICICI (INR) | I35: =IF(SMALL('Bills & Commitments'!$S$7:$S$80,1)>=99999,"",IFERROR(INDEX('Bills & Commitments'!$O$7:$O$80,MATCH(SMALL('Bills & Commitments'!$S$7:$S$80,1),'Bills & Commitments'!$S$7:$S$80,0)),"")) -> Estimated | J35: =IF(SMALL('Bills & Commitments'!$S$7:$S$80,1)>=99999,"",IFERROR(INDEX('Bills & Commitments'!$Q$7:$Q$80,MATCH(SMALL('Bills & Commitments'!$S$7:$S$80,1),'Bills & Commitments'!$S$7:$S$80,0)),"")) -> Scheduled | L35: =IF(SMALL('Bills & Commitments'!$S$7:$S$80,1)>=99999,"",IFERROR(INDEX('Bills & Commitments'!$P$7:$P$80,MATCH(SMALL('Bills & Commitments'!$S$7:$S$80,1),'Bills & Commitments'!$S$7:$S$80,0)),"")) -> 15
A36: =IF(SMALL('Bills & Commitments'!$S$7:$S$80,2)>=99999,"",IFERROR(INDEX('Bills & Commitments'!$B$7:$B$80,MATCH(SMALL('Bills & Commitments'!$S$7:$S$80,2),'Bills & Commitments'!$S$7:$S$80,0)),"")) -> du — September | D36: =IF(SMALL('Bills & Commitments'!$S$7:$S$80,2)>=99999,"",IFERROR(INDEX('Bills & Commitments'!$A$7:$A$80,MATCH(SMALL('Bills & Commitments'!$S$7:$S$80,2),'Bills & Commitments'!$S$7:$S$80,0)),"")) -> 46280 | F36: =IF(SMALL('Bills & Commitments'!$S$7:$S$80,2)>=99999,"",IFERROR(INDEX('Bills & Commitments'!$G$7:$G$80,MATCH(SMALL('Bills & Commitments'!$S$7:$S$80,2),'Bills & Commitments'!$S$7:$S$80,0)),"")) -> 590.98 | G36: =IF(SMALL('Bills & Commitments'!$S$7:$S$80,2)>=99999,"",IFERROR(INDEX('Bills & Commitments'!$K$7:$K$80,MATCH(SMALL('Bills & Commitments'!$S$7:$S$80,2),'Bills & Commitments'!$S$7:$S$80,0)),"")) -> FAB 4001 Current | I36: =IF(SMALL('Bills & Commitments'!$S$7:$S$80,2)>=99999,"",IFERROR(INDEX('Bills & Commitments'!$O$7:$O$80,MATCH(SMALL('Bills & Commitments'!$S$7:$S$80,2),'Bills & Commitments'!$S$7:$S$80,0)),"")) -> Estimated | J36: =IF(SMALL('Bills & Commitments'!$S$7:$S$80,2)>=99999,"",IFERROR(INDEX('Bills & Commitments'!$Q$7:$Q$80,MATCH(SMALL('Bills & Commitments'!$S$7:$S$80,2),'Bills & Commitments'!$S$7:$S$80,0)),"")) -> Scheduled | L36: =IF(SMALL('Bills & Commitments'!$S$7:$S$80,2)>=99999,"",IFERROR(INDEX('Bills & Commitments'!$P$7:$P$80,MATCH(SMALL('Bills & Commitments'!$S$7:$S$80,2),'Bills & Commitments'!$S$7:$S$80,0)),"")) -> 20
A37: =IF(SMALL('Bills & Commitments'!$S$7:$S$80,3)>=99999,"",IFERROR(INDEX('Bills & Commitments'!$B$7:$B$80,MATCH(SMALL('Bills & Commitments'!$S$7:$S$80,3),'Bills & Commitments'!$S$7:$S$80,0)),"")) -> Etisalat — September | D37: =IF(SMALL('Bills & Commitments'!$S$7:$S$80,3)>=99999,"",IFERROR(INDEX('Bills & Commitments'!$A$7:$A$80,MATCH(SMALL('Bills & Commitments'!$S$7:$S$80,3),'Bills & Commitments'!$S$7:$S$80,0)),"")) -> 46280 | F37: =IF(SMALL('Bills & Commitments'!$S$7:$S$80,3)>=99999,"",IFERROR(INDEX('Bills & Commitments'!$G$7:$G$80,MATCH(SMALL('Bills & Commitments'!$S$7:$S$80,3),'Bills & Commitments'!$S$7:$S$80,0)),"")) -> 323.95 | G37: =IF(SMALL('Bills & Commitments'!$S$7:$S$80,3)>=99999,"",IFERROR(INDEX('Bills & Commitments'!$K$7:$K$80,MATCH(SMALL('Bills & Commitments'!$S$7:$S$80,3),'Bills & Commitments'!$S$7:$S$80,0)),"")) -> FAB 4001 Current | I37: =IF(SMALL('Bills & Commitments'!$S$7:$S$80,3)>=99999,"",IFERROR(INDEX('Bills & Commitments'!$O$7:$O$80,MATCH(SMALL('Bills & Commitments'!$S$7:$S$80,3),'Bills & Commitments'!$S$7:$S$80,0)),"")) -> Estimated | J37: =IF(SMALL('Bills & Commitments'!$S$7:$S$80,3)>=99999,"",IFERROR(INDEX('Bills & Commitments'!$Q$7:$Q$80,MATCH(SMALL('Bills & Commitments'!$S$7:$S$80,3),'Bills & Commitments'!$S$7:$S$80,0)),"")) -> Scheduled | L37: =IF(SMALL('Bills & Commitments'!$S$7:$S$80,3)>=99999,"",IFERROR(INDEX('Bills & Commitments'!$P$7:$P$80,MATCH(SMALL('Bills & Commitments'!$S$7:$S$80,3),'Bills & Commitments'!$S$7:$S$80,0)),"")) -> 20
A38: =IF(SMALL('Bills & Commitments'!$S$7:$S$80,4)>=99999,"",IFERROR(INDEX('Bills & Commitments'!$B$7:$B$80,MATCH(SMALL('Bills & Commitments'!$S$7:$S$80,4),'Bills & Commitments'!$S$7:$S$80,0)),"")) -> DEWA — September | D38: =IF(SMALL('Bills & Commitments'!$S$7:$S$80,4)>=99999,"",IFERROR(INDEX('Bills & Commitments'!$A$7:$A$80,MATCH(SMALL('Bills & Commitments'!$S$7:$S$80,4),'Bills & Commitments'!$S$7:$S$80,0)),"")) -> 46295 | F38: =IF(SMALL('Bills & Commitments'!$S$7:$S$80,4)>=99999,"",IFERROR(INDEX('Bills & Commitments'!$G$7:$G$80,MATCH(SMALL('Bills & Commitments'!$S$7:$S$80,4),'Bills & Commitments'!$S$7:$S$80,0)),"")) -> 793.42 | G38: =IF(SMALL('Bills & Commitments'!$S$7:$S$80,4)>=99999,"",IFERROR(INDEX('Bills & Commitments'!$K$7:$K$80,MATCH(SMALL('Bills & Commitments'!$S$7:$S$80,4),'Bills & Commitments'!$S$7:$S$80,0)),"")) -> FAB 4001 Current | I38: =IF(SMALL('Bills & Commitments'!$S$7:$S$80,4)>=99999,"",IFERROR(INDEX('Bills & Commitments'!$O$7:$O$80,MATCH(SMALL('Bills & Commitments'!$S$7:$S$80,4),'Bills & Commitments'!$S$7:$S$80,0)),"")) -> Estimated | J38: =IF(SMALL('Bills & Commitments'!$S$7:$S$80,4)>=99999,"",IFERROR(INDEX('Bills & Commitments'!$Q$7:$Q$80,MATCH(SMALL('Bills & Commitments'!$S$7:$S$80,4),'Bills & Commitments'!$S$7:$S$80,0)),"")) -> Scheduled | L38: =IF(SMALL('Bills & Commitments'!$S$7:$S$80,4)>=99999,"",IFERROR(INDEX('Bills & Commitments'!$P$7:$P$80,MATCH(SMALL('Bills & Commitments'!$S$7:$S$80,4),'Bills & Commitments'!$S$7:$S$80,0)),"")) -> 35
A39: =IF(SMALL('Bills & Commitments'!$S$7:$S$80,5)>=99999,"",IFERROR(INDEX('Bills & Commitments'!$B$7:$B$80,MATCH(SMALL('Bills & Commitments'!$S$7:$S$80,5),'Bills & Commitments'!$S$7:$S$80,0)),"")) -> Tabby — September statement | D39: =IF(SMALL('Bills & Commitments'!$S$7:$S$80,5)>=99999,"",IFERROR(INDEX('Bills & Commitments'!$A$7:$A$80,MATCH(SMALL('Bills & Commitments'!$S$7:$S$80,5),'Bills & Commitments'!$S$7:$S$80,0)),"")) -> 46298 | F39: =IF(SMALL('Bills & Commitments'!$S$7:$S$80,5)>=99999,"",IFERROR(INDEX('Bills & Commitments'!$G$7:$G$80,MATCH(SMALL('Bills & Commitments'!$S$7:$S$80,5),'Bills & Commitments'!$S$7:$S$80,0)),"")) -> 715.33 | G39: =IF(SMALL('Bills & Commitments'!$S$7:$S$80,5)>=99999,"",IFERROR(INDEX('Bills & Commitments'!$K$7:$K$80,MATCH(SMALL('Bills & Commitments'!$S$7:$S$80,5),'Bills & Commitments'!$S$7:$S$80,0)),"")) -> FAB 4001 Current | I39: =IF(SMALL('Bills & Commitments'!$S$7:$S$80,5)>=99999,"",IFERROR(INDEX('Bills & Commitments'!$O$7:$O$80,MATCH(SMALL('Bills & Commitments'!$S$7:$S$80,5),'Bills & Commitments'!$S$7:$S$80,0)),"")) -> Actual | J39: =IF(SMALL('Bills & Commitments'!$S$7:$S$80,5)>=99999,"",IFERROR(INDEX('Bills & Commitments'!$Q$7:$Q$80,MATCH(SMALL('Bills & Commitments'!$S$7:$S$80,5),'Bills & Commitments'!$S$7:$S$80,0)),"")) -> Scheduled | L39: =IF(SMALL('Bills & Commitments'!$S$7:$S$80,5)>=99999,"",IFERROR(INDEX('Bills & Commitments'!$P$7:$P$80,MATCH(SMALL('Bills & Commitments'!$S$7:$S$80,5),'Bills & Commitments'!$S$7:$S$80,0)),"")) -> 38
A40: =IF(SMALL('Bills & Commitments'!$S$7:$S$80,6)>=99999,"",IFERROR(INDEX('Bills & Commitments'!$B$7:$B$80,MATCH(SMALL('Bills & Commitments'!$S$7:$S$80,6),'Bills & Commitments'!$S$7:$S$80,0)),"")) -> Nippon SIP — October | D40: =IF(SMALL('Bills & Commitments'!$S$7:$S$80,6)>=99999,"",IFERROR(INDEX('Bills & Commitments'!$A$7:$A$80,MATCH(SMALL('Bills & Commitments'!$S$7:$S$80,6),'Bills & Commitments'!$S$7:$S$80,0)),"")) -> 46305 | F40: =IF(SMALL('Bills & Commitments'!$S$7:$S$80,6)>=99999,"",IFERROR(INDEX('Bills & Commitments'!$G$7:$G$80,MATCH(SMALL('Bills & Commitments'!$S$7:$S$80,6),'Bills & Commitments'!$S$7:$S$80,0)),"")) -> 462.4 | G40: =IF(SMALL('Bills & Commitments'!$S$7:$S$80,6)>=99999,"",IFERROR(INDEX('Bills & Commitments'!$K$7:$K$80,MATCH(SMALL('Bills & Commitments'!$S$7:$S$80,6),'Bills & Commitments'!$S$7:$S$80,0)),"")) -> ICICI (INR) | I40: =IF(SMALL('Bills & Commitments'!$S$7:$S$80,6)>=99999,"",IFERROR(INDEX('Bills & Commitments'!$O$7:$O$80,MATCH(SMALL('Bills & Commitments'!$S$7:$S$80,6),'Bills & Commitments'!$S$7:$S$80,0)),"")) -> Estimated | J40: =IF(SMALL('Bills & Commitments'!$S$7:$S$80,6)>=99999,"",IFERROR(INDEX('Bills & Commitments'!$Q$7:$Q$80,MATCH(SMALL('Bills & Commitments'!$S$7:$S$80,6),'Bills & Commitments'!$S$7:$S$80,0)),"")) -> Scheduled | L40: =IF(SMALL('Bills & Commitments'!$S$7:$S$80,6)>=99999,"",IFERROR(INDEX('Bills & Commitments'!$P$7:$P$80,MATCH(SMALL('Bills & Commitments'!$S$7:$S$80,6),'Bills & Commitments'!$S$7:$S$80,0)),"")) -> 45
A41: =IF(SMALL('Bills & Commitments'!$S$7:$S$80,7)>=99999,"",IFERROR(INDEX('Bills & Commitments'!$B$7:$B$80,MATCH(SMALL('Bills & Commitments'!$S$7:$S$80,7),'Bills & Commitments'!$S$7:$S$80,0)),"")) -> du — October | D41: =IF(SMALL('Bills & Commitments'!$S$7:$S$80,7)>=99999,"",IFERROR(INDEX('Bills & Commitments'!$A$7:$A$80,MATCH(SMALL('Bills & Commitments'!$S$7:$S$80,7),'Bills & Commitments'!$S$7:$S$80,0)),"")) -> 46310 | F41: =IF(SMALL('Bills & Commitments'!$S$7:$S$80,7)>=99999,"",IFERROR(INDEX('Bills & Commitments'!$G$7:$G$80,MATCH(SMALL('Bills & Commitments'!$S$7:$S$80,7),'Bills & Commitments'!$S$7:$S$80,0)),"")) -> 590.98 | G41: =IF(SMALL('Bills & Commitments'!$S$7:$S$80,7)>=99999,"",IFERROR(INDEX('Bills & Commitments'!$K$7:$K$80,MATCH(SMALL('Bills & Commitments'!$S$7:$S$80,7),'Bills & Commitments'!$S$7:$S$80,0)),"")) -> FAB 4001 Current | I41: =IF(SMALL('Bills & Commitments'!$S$7:$S$80,7)>=99999,"",IFERROR(INDEX('Bills & Commitments'!$O$7:$O$80,MATCH(SMALL('Bills & Commitments'!$S$7:$S$80,7),'Bills & Commitments'!$S$7:$S$80,0)),"")) -> Estimated | J41: =IF(SMALL('Bills & Commitments'!$S$7:$S$80,7)>=99999,"",IFERROR(INDEX('Bills & Commitments'!$Q$7:$Q$80,MATCH(SMALL('Bills & Commitments'!$S$7:$S$80,7),'Bills & Commitments'!$S$7:$S$80,0)),"")) -> Scheduled | L41: =IF(SMALL('Bills & Commitments'!$S$7:$S$80,7)>=99999,"",IFERROR(INDEX('Bills & Commitments'!$P$7:$P$80,MATCH(SMALL('Bills & Commitments'!$S$7:$S$80,7),'Bills & Commitments'!$S$7:$S$80,0)),"")) -> 50
A42: =IF(SMALL('Bills & Commitments'!$S$7:$S$80,8)>=99999,"",IFERROR(INDEX('Bills & Commitments'!$B$7:$B$80,MATCH(SMALL('Bills & Commitments'!$S$7:$S$80,8),'Bills & Commitments'!$S$7:$S$80,0)),"")) -> Etisalat — October | D42: =IF(SMALL('Bills & Commitments'!$S$7:$S$80,8)>=99999,"",IFERROR(INDEX('Bills & Commitments'!$A$7:$A$80,MATCH(SMALL('Bills & Commitments'!$S$7:$S$80,8),'Bills & Commitments'!$S$7:$S$80,0)),"")) -> 46310 | F42: =IF(SMALL('Bills & Commitments'!$S$7:$S$80,8)>=99999,"",IFERROR(INDEX('Bills & Commitments'!$G$7:$G$80,MATCH(SMALL('Bills & Commitments'!$S$7:$S$80,8),'Bills & Commitments'!$S$7:$S$80,0)),"")) -> 323.95 | G42: =IF(SMALL('Bills & Commitments'!$S$7:$S$80,8)>=99999,"",IFERROR(INDEX('Bills & Commitments'!$K$7:$K$80,MATCH(SMALL('Bills & Commitments'!$S$7:$S$80,8),'Bills & Commitments'!$S$7:$S$80,0)),"")) -> FAB 4001 Current | I42: =IF(SMALL('Bills & Commitments'!$S$7:$S$80,8)>=99999,"",IFERROR(INDEX('Bills & Commitments'!$O$7:$O$80,MATCH(SMALL('Bills & Commitments'!$S$7:$S$80,8),'Bills & Commitments'!$S$7:$S$80,0)),"")) -> Estimated | J42: =IF(SMALL('Bills & Commitments'!$S$7:$S$80,8)>=99999,"",IFERROR(INDEX('Bills & Commitments'!$Q$7:$Q$80,MATCH(SMALL('Bills & Commitments'!$S$7:$S$80,8),'Bills & Commitments'!$S$7:$S$80,0)),"")) -> Scheduled | L42: =IF(SMALL('Bills & Commitments'!$S$7:$S$80,8)>=99999,"",IFERROR(INDEX('Bills & Commitments'!$P$7:$P$80,MATCH(SMALL('Bills & Commitments'!$S$7:$S$80,8),'Bills & Commitments'!$S$7:$S$80,0)),"")) -> 50
A44: ALERTS
A45: =IF(Settings!$B$72<0,"● CRITICAL — projected rent funding is short by AED "&TEXT(Settings!$B$81,"#,##0.00")&". Living budget to 21 Oct is effectively zero without new income.","") -> ● CRITICAL — projected rent funding is short by AED 3,091.03. Living budget to 21 Oct is effectively zero without new income.
A46: =IF(COUNTIFS('Bills & Commitments'!$Q$7:$Q$80,"OVERDUE")>0,"● A bill is OVERDUE — see the obligations table above.","")
A47: =IF(Settings!$B$94<0,"● Projected month-end cash is negative at the current burn rate.","") -> ● Projected month-end cash is negative at the current burn rate.
A48: =IF(Settings!$B$90>Settings!$B$75,"● Spending is running above the safe pace: AED "&TEXT(Settings!$B$90,"#,##0.00")&"/day actual vs AED "&TEXT(Settings!$B$75,"#,##0.00")&"/day allowed.","") -> ● Spending is running above the safe pace: AED 119.99/day actual vs AED 0.00/day allowed.
...

Sheet Today's Brief
B1: TODAY'S CFO BRIEF
B2: ="Prepared for "&Settings!$B$7&" · "&TEXT(Settings!$B$9,"dddd, dd mmmm yyyy") -> Prepared for Johnny · Wednesday, 26 August 2026
B5: ="Today you hold AED "&TEXT(Settings!$B$60,"#,##0.00")&" in total liquid cash across every account." -> Today you hold AED 6,105.17 in total liquid cash across every account.
B8: ="Of that, AED "&TEXT(Settings!$B$61,"#,##0.00")&" is protected — the rent vault and the emergency fund. Your true usable balance is AED "&TEXT(Settings!$B$62,"#,##0.00")&"." -> Of that, AED 5,948.37 is protected — the rent vault and the emergency fund. Your true usable balance is AED 156.80.
B11: ="There are "&Settings!$B$66&" days until your next income on "&TEXT(Settings!$B$12,"dd mmmm")&", and "&Settings!$B$73&" days until the rent cheque must be fully funded on "&TEXT(Settings!$B$21,"dd mmmm")&"." -> There are 31 days until your next income on 26 September, and 56 days until the rent cheque must be fully funded on 21 October.
B14: ="Recommended spending ceiling THIS WEEK: AED "&TEXT(Settings!$B$75*7,"#,##0.00")&". Survival week: AED "&TEXT(Settings!$B$76*7,"#,##0.00")&". Comfortable week: "&IF(Settings!$B$77=0,"not available yet.","AED "&TEXT(Settings!$B$77*7,"#,##0.00")&".") -> Recommended spending ceiling THIS WEEK: AED 0.00. Survival week: AED -332.06. Comfortable week: not available yet.
B17: ="Recommended ceiling for the whole weekend: AED "&TEXT(Settings!$B$78,"#,##0.00")&"." -> Recommended ceiling for the whole weekend: AED 0.00.
B20: ="Next payment: "&Settings!$B$103&" — AED "&TEXT(Settings!$B$102,"#,##0.00")&" on "&TEXT(Settings!$B$104,"dd mmmm")&"." -> Next payment: Nippon SIP — September — AED 462.40 on 10 September.
B23: ="Largest payment before the rent deadline: "&Settings!$B$106&" — AED "&TEXT(Settings!$B$105,"#,##0.00")&" on "&TEXT(Settings!$B$107,"dd mmmm")&"." -> Largest payment before the rent deadline: DEWA — September — AED 793.42 on 30 September.
B26: ="At your current burn rate of AED "&TEXT(Settings!$B$90,"#,##0.00")&" a day, projected month-end cash is AED "&TEXT(Settings!$B$94,"#,##0.00")&"." -> At your current burn rate of AED 119.99 a day, projected month-end cash is AED -443.16.
B29: ="MAIN RISK: "&IF(Settings!$B$72<0,"the October rent cheque. After every confirmed commitment you are AED "&TEXT(Settings!$B$81,"#,##0.00")&" short of funding it, and that assumes the AED 1,430 refund and AED 1,540 pending salary both land. If both fail, add AED 2,970.",IF(Settings!$B$99<0.25,"you have almost no emergency cover. One unexpected bill becomes debt.","spending drift above the safe daily pace.")) -> MAIN RISK: the October rent cheque. After every confirmed commitment you are AED 3,091.03 short of funding it, and that assumes the AED 1,430 refund and AED 1,540 pending salary both land. If both fail, add AED 2,970.
B32: ="ACTION TODAY: "&IF(Settings!$B$72<0,"earn or recover AED "&TEXT(Settings!$B$82,"#,##0.00")&" today (AED "&TEXT(Settings!$B$83,"#,##0.00")&" this week), and hold spending at or below AED "&TEXT(Settings!$B$76,"#,##0.00")&". Do not release a dirham against money that has not landed.","hold spending at or below AED "&TEXT(Settings!$B$75,"#,##0.00")&" and move any surplus into the rent vault.") -> ACTION TODAY: earn or recover AED 55.20 today (AED 386.38 this week), and hold spending at or below AED -47.44. Do not release a dirham against money that has not landed.
B35: Every figure above is a live formula. Nothing here is typed by hand — change a balance on the Accounts sheet or add a transaction and this brief rewrites itself.
B38: HOW TO KEEP THIS ALIVE · under one minute a day
B39: 1. Add the day's spending to the Transactions sheet — Date, Account, Type, Category, Merchant, Amount. Everything else is a dropdown or fills itself.
B40: 2. Update the Current Balance column on the Accounts sheet whenever you check your bank. That single column drives the whole dashboard.
B41: 3. When a bill is paid, put the real figure in the Actual column on Bills & Commitments and set Settled to Yes. Never delete the row.
B42: 4. Once a month, open Reconciliation. If an account says RECONCILIATION REQUIRED, a transaction is missing — find it before you trust any projection.
B43: 5. Change assumptions only on the Settings sheet. Nothing is hardcoded anywhere else.

Sheet Settings
A1: Control Panel
A2: Every assumption in the workbook lives here. Edit only the blue text on yellow fill — nothing else is hardcoded elsewhere.
A5: CORE ASSUMPTIONS · edit yellow cells only
A6: Setting | B6: Value | C6: Unit | D6: Note / source
A7: Owner | B7: Johnny | C7: – | D7: Workbook owner
A8: Base currency | B8: AED | C8: – | D8: All dashboard figures are AED unless labelled
A9: As-of date (automatic) | B9: =TODAY() -> 46260 | C9: date | D9: Recalculates every time the file is opened
A10: Monthly salary — base | B10: 7914.88 | C10: AED | D10: July 2026 salary baseline
A11: Salary day of month | B11: 26 | C11: day | D11: Credit day
A12: Next income date | B12: =IF(DAY($B$9)<$B$11,DATE(YEAR($B$9),MONTH($B$9),$B$11),DATE(YEAR($B$9),MONTH($B$9)+1,$B$11)) -> 46291 | C12: date | D12: Derived from the salary day. On payday itself the salary has landed, so the count rolls to next month — with <= it returned zero days, which drove the safe daily limit to zero on the one day of the month you are paid.
A13: Days until next income | B13: =MAX($B$12-$B$9,0) -> 31 | C13: days | D13: Derived
A14: Minimum cash safety buffer | B14: 250 | C14: AED | D14: Cash you refuse to go below
A15: Minimum living need per day | B15: 15 | C15: AED/day | D15: Floor for food/transport — the control cap basis
A16: Comfortable-mode multiplier | B16: 1.35 | C16: x | D16: Only displayed if finances support it
A17: Survival-mode multiplier | B17: 0.65 | C17: x | D17: Emergency compression
A18: Weekend length | B18: 2 | C18: days | D18: Used for the weekend allowance
A19: Rent cheque amount | B19: 11750 | C19: AED | D19: Lease schedule
A20: Rent cheque date | B20: 46317 | C20: date | D20: Cheque clears this day
A21: Rent must be fully funded by | B21: =$B$20-1 -> 46316 | C21: date | D21: One day before clearing — the 26 Oct salary is too late
A22: Days until rent funding deadline | B22: =MAX($B$21-$B$9,0) -> 56 | C22: days | D22: Derived — the binding constraint
A23: Emergency fund target | B23: 1000 | C23: AED | D23: Next milestone
A24: DEWA monthly baseline | B24: 793.42 | C24: AED | D24: Last confirmed bill — replace when actual arrives
A25: du monthly baseline | B25: 590.98 | C25: AED | D25: Paid 03 Aug
A26: Etisalat monthly baseline | B26: 323.95 | C26: AED | D26: Paid 03 Aug
A27: Monthly SIP | B27: 12000 | C27: INR | D27: Four Nippon SIPs
A28: INR to AED rate | B28: 0.0385333 | C28: rate | D28: Implied by AED 462.40 = INR 12,000
A29: Monthly SIP (AED equivalent) | B29: =ROUND($B$27*$B$28,2) -> 462.4 | C29: AED | D29: Derived
A30: Tabby no-fee minimum | B30: 1314.5 | C30: AED | D30: September statement option
A31: Tabby full statement | B31: 1972.03 | C31: AED | D31: Optional full clearance
A32: Tabby total outstanding exposure | B32: 2687.36 | C32: AED | D32: Resolves as: 1,314.50 (Aug stmt, 3 Sep) + 715.33 (Sep stmt, 3 Oct) + 657.53 (Oct stmt, ~3 Nov, not yet generated). CONFIRMED via Tabby chat 15 Aug.
A34: USD to AED rate (fixed peg) | B34: 3.6725 | D34: AED's fixed dirham peg — has not moved since 1997
A35: Amana ending value (USD) | B35: 864.82 | D35: Statement ending 10 Aug 2026 | F35: Categories | G35: Classes | H35: Transaction types | I35: Accounts | J35: Essential? | K35: Fixed / Variable | L35: Yes / No | M35: Certainty
F36: Salary | G36: Household | H36: Income | I36: FAB 4001 Current | J36: Essential | K36: Fixed | L36: Yes | M36: Actual
F37: Side Income | G37: Personal | H37: Expense | I37: FAB 4002 Home Expenditure | J37: Non-Essential | K37: Variable | L37: No | M37: Estimated
F38: Refund / Reimbursement | G38: Financial | H38: Transfer In | I38: FAB 4003 Emergency Fund | M38: Possible
F39: Groceries | G39: Income | H39: Transfer Out | I39: NBD Current
F40: Food & Dining | G40: Internal | I40: NBD Plus Saver
F41: Utilities | G41: Business | I41: Tabby Cash
F42: Telecom | I42: Cash / Wio
F43: Transport | I43: ICICI (INR)
...

Sheet Accounts
A1: Accounts & Cash Control
A2: Money that exists · money already committed · money genuinely available. These three are never mixed.
A5: ACCOUNT REGISTER
A6: Account | B6: Type | C6: Currency | D6: Current Balance | E6: Reserved / Committed | F6: Available to Spend | G6: Counts as AED liquid cash? | H6: Purpose | I6: Last Updated | J6: Notes
A7: FAB 4001 Current | B7: Bank | C7: AED | D7: 14.95 | E7: 0 | F7: =D7-E7 -> 14.95 | G7: Yes | H7: Day-to-day spending | I7: 46260 | J7: Card XXXX1599. Emarat fuel (13.50), 18:20.
A8: FAB 4002 Home Expenditure | B8: Bank | C8: AED | D8: 5940.7 | E8: 5940.7 | F8: =D8-E8 -> 0 | G8: Yes | H8: Rent vault | I8: 46259 | J8: Rent vault. AED 150 moved out for home expenditure, per owner. 50.6% funded.
A9: FAB 4003 Emergency Fund | B9: Savings | C9: AED | D9: 7.67 | E9: =D9 -> 7.67 | F9: =D9-E9 -> 0 | G9: Yes | H9: Emergency fund | I9: 46245 | J9: Next milestone AED 1,000
A10: NBD Current | B10: Bank | C10: AED | D10: 138.23 | E10: 0 | F10: =D10-E10 -> 138.23 | G10: Yes | H10: Secondary current | I10: 46260 | J10: Card 3695. Cielo Kabab, Emarat 6192, Netflix (actual 36.09, not the ~35.00 shown) all cleared today.
A11: NBD Plus Saver | B11: Savings | C11: AED | D11: 2.73 | E11: 0 | F11: =D11-E11 -> 2.73 | G11: Yes | H11: Savings sub-account | I11: 46239 | J11: Includes AED 1.64 interest credit
A12: Tabby Cash | B12: Wallet | C12: AED | D12: 0.89 | E12: 0 | F12: =D12-E12 -> 0.89 | G12: Yes | H12: Funded wallet | I12: 46238 | J12: Wallet money — NOT Tabby Card borrowing
A13: Cash / Wio | B13: Cash | C13: AED | D13: 0 | E13: 0 | F13: =D13-E13 -> 0 | G13: Yes | H13: Physical cash | I13: 46245 | J13: No balance reported
A14: ICICI (INR) | B14: Bank | C14: INR | D14: 12388.51 | E14: 0 | F14: =D14-E14 -> 12388.51 | G14: No | H14: SIP funding account | I14: 46260 | J14: CONFIRMED via ICICI app screenshot, personal India account. Fresh remittance (INR 12,000 from today's SIP transfer) just landed. Monthly SIP auto-debit will pull ~12,000 from here, returning balance to ~388.51 until next month's remittance. Personal, not part of AED household calculations.
A15: TOTAL — AED liquid | D15: =SUMIFS(D7:D14,C7:C14,"AED",G7:G14,"Yes") -> 6105.17 | E15: =SUMIFS(E7:E14,C7:C14,"AED",G7:G14,"Yes") -> 5948.37 | F15: =D15-E15 -> 156.8 | H15: ="Ties to AED "&TEXT($D$15,"#,##0.00")&" — recomputed, never typed" -> Ties to AED 6,105.17 — recomputed, never typed
H16: FAB 4002 is now flagged as the rent vault, so its full balance is treated as committed. If any part of it is really a utilities float, lower the Reserved figure and the dashboard re-rates instantly.
A17: WHAT THE THREE COLUMNS MEAN
A18: Current Balance | B18: Money that exists in the account right now.
A19: Reserved / Committed | B19: Money physically present but already spoken for — rent vault and emergency fund. Spending it breaks a commitment.
A20: Available to Spend | B20: Balance minus reserved. This is the only number that may fund discretionary spending, and it is still reduced by upcoming bills on the dashboard.

Sheet Account History
A1: Account Balance History
A2: Every balance you've ever recorded, per account, over time. Add a new row each time you check a balance — the trend chart and per-account summary update automatically.
A5: BALANCE LOG · add a row per account per check-in | G5: LATEST BALANCE PER ACCOUNT · pulls the most recent dated entry for each
A6: Date | B6: Account | C6: Balance | D6: Change vs last entry | E6: Note | G6: Account | H6: Latest balance | I6: As of | J6: Entries logged
A7: 46229 | B7: FAB 4001 Current | D7: =IF($C7="","",IFERROR($C7-LOOKUP(2,1/(($B$7:$B6=$B7)*($A$7:$A6<$A7)),$C$7:$C6),"")) | E7: Approx. — DEWA July paid this date · Balance not recorded for this date; left blank so the latest-balance lookup skips it rather than returning text. | G7: FAB 4001 Current | H7: =IFERROR(LOOKUP(2,1/(($B$7:$B$100=$G7)*($C$7:$C$100<>"")),$C$7:$C$100),"No data") -> 14.95 | I7: =IFERROR(LOOKUP(2,1/(($B$7:$B$100=$G7)*($C$7:$C$100<>"")),$A$7:$A$100),"") -> 46260 | J7: =COUNTIF($B$7:$B$100,$G7) -> 4
A8: 46237 | B8: FAB 4001 Current | D8: =IF($C8="","",IFERROR($C8-LOOKUP(2,1/(($B$7:$B7=$B8)*($A$7:$A7<$A8)),$C$7:$C7),"")) | E8: du + Etisalat paid via DubaiPay · Balance not recorded for this date; left blank so the latest-balance lookup skips it rather than returning text. | G8: FAB 4002 Home Expenditure | H8: =IFERROR(LOOKUP(2,1/(($B$7:$B$100=$G8)*($C$7:$C$100<>"")),$C$7:$C$100),"No data") -> 5940.7 | I8: =IFERROR(LOOKUP(2,1/(($B$7:$B$100=$G8)*($C$7:$C$100<>"")),$A$7:$A$100),"") -> 46259 | J8: =COUNTIF($B$7:$B$100,$G8) -> 2
A9: 46238 | B9: NBD Plus Saver | C9: 2.73 | D9: =IF($C9="","",IFERROR($C9-LOOKUP(2,1/(($B$7:$B8=$B9)*($A$7:$A8<$A9)),$C$7:$C8),"")) | E9: Includes AED 1.64 interest credit | G9: FAB 4003 Emergency Fund | H9: =IFERROR(LOOKUP(2,1/(($B$7:$B$100=$G9)*($C$7:$C$100<>"")),$C$7:$C$100),"No data") -> 7.67 | I9: =IFERROR(LOOKUP(2,1/(($B$7:$B$100=$G9)*($C$7:$C$100<>"")),$A$7:$A$100),"") -> 46245 | J9: =COUNTIF($B$7:$B$100,$G9) -> 1
A10: 46238 | B10: Tabby Cash | C10: 0.89 | D10: =IF($C10="","",IFERROR($C10-LOOKUP(2,1/(($B$7:$B9=$B10)*($A$7:$A9<$A10)),$C$7:$C9),"")) | E10: Funded wallet | G10: NBD Current | H10: =IFERROR(LOOKUP(2,1/(($B$7:$B$100=$G10)*($C$7:$C$100<>"")),$C$7:$C$100),"No data") -> 138.23 | I10: =IFERROR(LOOKUP(2,1/(($B$7:$B$100=$G10)*($C$7:$C$100<>"")),$A$7:$A$100),"") -> 46260 | J10: =COUNTIF($B$7:$B$100,$G10) -> 4
A11: 46239 | B11: NBD Current | C11: 15.7 | D11: =IF($C11="","",IFERROR($C11-LOOKUP(2,1/(($B$7:$B10=$B11)*($A$7:$A10<$A11)),$C$7:$C10),"")) | E11: Last point before the unidentified AED 13.50 spend | G11: NBD Plus Saver | H11: =IFERROR(LOOKUP(2,1/(($B$7:$B$100=$G11)*($C$7:$C$100<>"")),$C$7:$C$100),"No data") -> 2.73 | I11: =IFERROR(LOOKUP(2,1/(($B$7:$B$100=$G11)*($C$7:$C$100<>"")),$A$7:$A$100),"") -> 46238 | J11: =COUNTIF($B$7:$B$100,$G11) -> 1
A12: 46240 | B12: NBD Current | C12: 2.2 | D12: =IF($C12="","",IFERROR($C12-LOOKUP(2,1/(($B$7:$B11=$B12)*($A$7:$A11<$A12)),$C$7:$C11),"")) -> -13.5 | E12: Last reported before the workbook was built | G12: Tabby Cash | H12: =IFERROR(LOOKUP(2,1/(($B$7:$B$100=$G12)*($C$7:$C$100<>"")),$C$7:$C$100),"No data") -> 0.89 | I12: =IFERROR(LOOKUP(2,1/(($B$7:$B$100=$G12)*($C$7:$C$100<>"")),$A$7:$A$100),"") -> 46238 | J12: =COUNTIF($B$7:$B$100,$G12) -> 1
A13: 46244 | B13: ICICI (INR) | C13: 388.51 | D13: =IF($C13="","",IFERROR($C13-LOOKUP(2,1/(($B$7:$B12=$B13)*($A$7:$A12<$A13)),$C$7:$C12),"")) | E13: After four Nippon SIPs completed | G13: Cash / Wio | H13: =IFERROR(LOOKUP(2,1/(($B$7:$B$100=$G13)*($C$7:$C$100<>"")),$C$7:$C$100),"No data") -> 0 | I13: =IFERROR(LOOKUP(2,1/(($B$7:$B$100=$G13)*($C$7:$C$100<>"")),$A$7:$A$100),"") -> 46245 | J13: =COUNTIF($B$7:$B$100,$G13) -> 1
A14: 46245 | B14: FAB 4001 Current | C14: 245.09 | D14: =IF($C14="","",IFERROR($C14-LOOKUP(2,1/(($B$7:$B13=$B14)*($A$7:$A13<$A14)),$C$7:$C13),"")) -> 245.09 | E14: Confirmed by the FAB app — card XXXX1599 | G14: ICICI (INR) | H14: =IFERROR(LOOKUP(2,1/(($B$7:$B$100=$G14)*($C$7:$C$100<>"")),$C$7:$C$100),"No data") -> 12388.51 | I14: =IFERROR(LOOKUP(2,1/(($B$7:$B$100=$G14)*($C$7:$C$100<>"")),$A$7:$A$100),"") -> 46260 | J14: =COUNTIF($B$7:$B$100,$G14) -> 2
A15: 46245 | B15: FAB 4002 Home Expenditure | C15: 4004.61 | D15: =IF($C15="","",IFERROR($C15-LOOKUP(2,1/(($B$7:$B14=$B15)*($A$7:$A14<$A15)),$C$7:$C14),"")) | E15: Confirmed by the FAB app — designated rent vault
A16: 46245 | B16: FAB 4003 Emergency Fund | C16: 7.67 | D16: =IF($C16="","",IFERROR($C16-LOOKUP(2,1/(($B$7:$B15=$B16)*($A$7:$A15<$A16)),$C$7:$C15),"")) | E16: Confirmed by the FAB app
A17: 46245 | B17: NBD Current | C17: 2.2 | D17: =IF($C17="","",IFERROR($C17-LOOKUP(2,1/(($B$7:$B16=$B17)*($A$7:$A16<$A17)),$C$7:$C16),"")) -> 0 | E17: Confirmed
A18: 46245 | B18: Cash / Wio | C18: 0 | D18: =IF($C18="","",IFERROR($C18-LOOKUP(2,1/(($B$7:$B17=$B18)*($A$7:$A17<$A18)),$C$7:$C17),"")) | E18: No balance reported
A19: 46259 | B19: FAB 4002 Home Expenditure | C19: 5940.7 | D19: =IF($C19="","",IFERROR($C19-LOOKUP(2,1/(($B$7:$B18=$B19)*($A$7:$A18<$A19)),$C$7:$C18),"")) -> 1936.09 | E19: Confirmed on the Accounts sheet. AED 150 moved out for home expenditure.
A20: 46260 | B20: FAB 4001 Current | C20: 14.95 | D20: =IF($C20="","",IFERROR($C20-LOOKUP(2,1/(($B$7:$B19=$B20)*($A$7:$A19<$A20)),$C$7:$C19),"")) -> -230.14 | E20: Confirmed on the Accounts sheet. Card XXXX1599, Emarat fuel 13.50 at 18:20.
A21: 46260 | B21: NBD Current | C21: 138.23 | D21: =IF($C21="","",IFERROR($C21-LOOKUP(2,1/(($B$7:$B20=$B21)*($A$7:$A20<$A21)),$C$7:$C20),"")) -> 136.03 | E21: Confirmed on the Accounts sheet. Cielo Kabab, Emarat 6192 and Netflix 36.09 cleared.
A22: 46260 | B22: ICICI (INR) | C22: 12388.51 | D22: =IF($C22="","",IFERROR($C22-LOOKUP(2,1/(($B$7:$B21=$B22)*($A$7:$A21<$A22)),$C$7:$C21),"")) -> 12000 | E22: Confirmed via the ICICI app. Fresh INR 12,000 remittance landed for the SIP.
D23: =IF($C23="","",IFERROR($C23-LOOKUP(2,1/(($B$7:$B22=$B23)*($A$7:$A22<$A23)),$C$7:$C22),""))
A24: The latest-balance summary now sits to the right, at column G — it had to move out of columns A–E because it was reading the very range it lives in. Rows below here are free for new log entries.
D25: =IF($C25="","",IFERROR($C25-LOOKUP(2,1/(($B$7:$B24=$B25)*($A$7:$A24<$A25)),$C$7:$C24),""))
D26: =IF($C26="","",IFERROR($C26-LOOKUP(2,1/(($B$7:$B25=$B26)*($A$7:$A25<$A26)),$C$7:$C25),""))
D27: =IF($C27="","",IFERROR($C27-LOOKUP(2,1/(($B$7:$B26=$B27)*($A$7:$A26<$A27)),$C$7:$C26),""))
D28: =IF($C28="","",IFERROR($C28-LOOKUP(2,1/(($B$7:$B27=$B28)*($A$7:$A27<$A28)),$C$7:$C27),""))
D29: =IF($C29="","",IFERROR($C29-LOOKUP(2,1/(($B$7:$B28=$B29)*($A$7:$A28<$A29)),$C$7:$C28),""))
D30: =IF($C30="","",IFERROR($C30-LOOKUP(2,1/(($B$7:$B29=$B30)*($A$7:$A29<$A30)),$C$7:$C29),""))
D31: =IF($C31="","",IFERROR($C31-LOOKUP(2,1/(($B$7:$B30=$B31)*($A$7:$A30<$A31)),$C$7:$C30),""))
D32: =IF($C32="","",IFERROR($C32-LOOKUP(2,1/(($B$7:$B31=$B32)*($A$7:$A31<$A32)),$C$7:$C31),""))
D33: =IF($C33="","",IFERROR($C33-LOOKUP(2,1/(($B$7:$B32=$B33)*($A$7:$A32<$A33)),$C$7:$C32),""))
D34: =IF($C34="","",IFERROR($C34-LOOKUP(2,1/(($B$7:$B33=$B34)*($A$7:$A33<$A34)),$C$7:$C33),""))
D35: =IF($C35="","",IFERROR($C35-LOOKUP(2,1/(($B$7:$B34=$B35)*($A$7:$A34<$A35)),$C$7:$C34),""))
D36: =IF($C36="","",IFERROR($C36-LOOKUP(2,1/(($B$7:$B35=$B36)*($A$7:$A35<$A36)),$C$7:$C35),""))
... D100: =IF($C100="","",IFERROR($C100-LOOKUP(2,1/(($B$7:$B99=$B100)*($A$7:$A99<$A100)),$C$7:$C99),""))

Sheet Transactions
A1: Master Transaction Database
A2: One row per movement of money. Type your entry in the first empty row — grey columns fill themselves. Transfers never count as spending.
A4: QUICK ADD → you only need to fill: Date · Account · Type · Category · Merchant · Amount. Everything else is optional or automatic.
A6: ID | B6: Date | C6: Month | D6: Year | E6: Account | F6: Type | G6: Category | H6: Subcategory | I6: Merchant / Payee | J6: Class | K6: Fixed / Var | L6: Essential? | M6: Payment Method | N6: Recurring? | O6: Amount | P6: Currency | Q6: Cash Impact (AED) | R6: Related Bill | S6: Verified? | T6: Notes | U6: Original timestamp
A7: =IF($B7="","","T"&TEXT(ROW()-6,"0000")) -> T1.00 | B7: 46237 | C7: =IF($B7="","",TEXT($B7,"YYYY-MM")) -> 2026-08 | D7: =IF($B7="","",YEAR($B7)) -> 2026 | E7: FAB 4001 Current | F7: Expense | G7: Utilities | H7: du + Etisalat | I7: du + Etisalat via DubaiPay | J7: Household | K7: Fixed | L7: Essential | M7: Card | N7: Yes | O7: 914.93 | P7: AED | Q7: =IF($B7="","",IF($P7<>"AED",0,IF($F7="Income",$O7,IF($F7="Expense",-$O7,0)))) -> -914.93 | R7: du August | S7: Yes | T7: Paid once — du 590.98 + Etisalat 323.95 | U7: 2026-08-03 11:20
A8: =IF($B8="","","T"&TEXT(ROW()-6,"0000")) -> T2.00 | B8: 46237 | C8: =IF($B8="","",TEXT($B8,"YYYY-MM")) -> 2026-08 | D8: =IF($B8="","",YEAR($B8)) -> 2026 | E8: NBD Current | F8: Expense | G8: Lifestyle | H8: Convenience store | I8: Asas Al Madina General | J8: Personal | K8: Variable | L8: Non-Essential | M8: Card | N8: No | O8: 14 | P8: AED | Q8: =IF($B8="","",IF($P8<>"AED",0,IF($F8="Income",$O8,IF($F8="Expense",-$O8,0)))) -> -14 | S8: Yes | U8: 2026-08-03 12:00
A9: =IF($B9="","","T"&TEXT(ROW()-6,"0000")) -> T3.00 | B9: 46237 | C9: =IF($B9="","",TEXT($B9,"YYYY-MM")) -> 2026-08 | D9: =IF($B9="","",YEAR($B9)) -> 2026 | E9: NBD Current | F9: Expense | G9: Household Other | H9: Home supplies | I9: Yas Home General Trading | J9: Household | K9: Variable | L9: Essential | M9: Card | N9: No | O9: 22.97 | P9: AED | Q9: =IF($B9="","",IF($P9<>"AED",0,IF($F9="Income",$O9,IF($F9="Expense",-$O9,0)))) -> -22.97 | S9: Yes | U9: 2026-08-03 13:00
A10: =IF($B10="","","T"&TEXT(ROW()-6,"0000")) -> T4.00 | B10: 46237 | C10: =IF($B10="","",TEXT($B10,"YYYY-MM")) -> 2026-08 | D10: =IF($B10="","",YEAR($B10)) -> 2026 | E10: NBD Current | F10: Expense | G10: Food & Dining | H10: Restaurant | I10: Spicy Falcon Restaurant | J10: Household | K10: Variable | L10: Non-Essential | M10: Card | N10: No | O10: 16 | P10: AED | Q10: =IF($B10="","",IF($P10<>"AED",0,IF($F10="Income",$O10,IF($F10="Expense",-$O10,0)))) -> -16 | S10: Yes | U10: 2026-08-03 20:04
A11: =IF($B11="","","T"&TEXT(ROW()-6,"0000")) -> T5.00 | B11: 46238 | C11: =IF($B11="","",TEXT($B11,"YYYY-MM")) -> 2026-08 | D11: =IF($B11="","",YEAR($B11)) -> 2026 | E11: NBD Current | F11: Expense | G11: Lifestyle | H11: Fuel / convenience | I11: Emarat Nad Al Hamar | J11: Personal | K11: Variable | L11: Non-Essential | M11: Card | N11: No | O11: 13.5 | P11: AED | Q11: =IF($B11="","",IF($P11<>"AED",0,IF($F11="Income",$O11,IF($F11="Expense",-$O11,0)))) -> -13.5 | S11: Yes | U11: 2026-08-04 04:42
A12: =IF($B12="","","T"&TEXT(ROW()-6,"0000")) -> T6.00 | B12: 46238 | C12: =IF($B12="","",TEXT($B12,"YYYY-MM")) -> 2026-08 | D12: =IF($B12="","",YEAR($B12)) -> 2026 | E12: Tabby Cash | F12: Expense | G12: Lifestyle | H12: Convenience store | I12: Nad Al Hamar Star Grocery | J12: Personal | K12: Variable | L12: Non-Essential | M12: Wallet | N12: No | O12: 2 | P12: AED | Q12: =IF($B12="","",IF($P12<>"AED",0,IF($F12="Income",$O12,IF($F12="Expense",-$O12,0)))) -> -2 | S12: Yes | T12: Tabby Cash wallet — never Tabby Card debt | U12: 2026-08-04 05:00
A13: =IF($B13="","","T"&TEXT(ROW()-6,"0000")) -> T7.00 | B13: 46238 | C13: =IF($B13="","",TEXT($B13,"YYYY-MM")) -> 2026-08 | D13: =IF($B13="","",YEAR($B13)) -> 2026 | E13: NBD Current | F13: Expense | G13: Groceries | H13: Grocery | I13: Asas Al Madina General | J13: Household | K13: Variable | L13: Essential | M13: Card | N13: No | O13: 24.5 | P13: AED | Q13: =IF($B13="","",IF($P13<>"AED",0,IF($F13="Income",$O13,IF($F13="Expense",-$O13,0)))) -> -24.5 | S13: Yes | U13: 2026-08-04 08:00
A14: =IF($B14="","","T"&TEXT(ROW()-6,"0000")) -> T8.00 | B14: 46239 | C14: =IF($B14="","",TEXT($B14,"YYYY-MM")) -> 2026-08 | D14: =IF($B14="","",YEAR($B14)) -> 2026 | E14: NBD Current | F14: Expense | G14: Entertainment | H14: Cinema | I14: Reel Entertainment | J14: Personal | K14: Variable | L14: Non-Essential | M14: Card | N14: No | O14: 20 | P14: AED | Q14: =IF($B14="","",IF($P14<>"AED",0,IF($F14="Income",$O14,IF($F14="Expense",-$O14,0)))) -> -20 | S14: Yes | T14: Reclassified from Household Other — this is discretionary | U14: 2026-08-05 07:48
A15: =IF($B15="","","T"&TEXT(ROW()-6,"0000")) -> T9.00 | B15: 46239 | C15: =IF($B15="","",TEXT($B15,"YYYY-MM")) -> 2026-08 | D15: =IF($B15="","",YEAR($B15)) -> 2026 | E15: NBD Current | F15: Expense | G15: Food & Dining | H15: Cafe | I15: HNS Restaurant and Cafe | J15: Household | K15: Variable | L15: Non-Essential | M15: Card | N15: No | O15: 10 | P15: AED | Q15: =IF($B15="","",IF($P15<>"AED",0,IF($F15="Income",$O15,IF($F15="Expense",-$O15,0)))) -> -10 | S15: Yes | U15: 2026-08-05 10:46
A16: =IF($B16="","","T"&TEXT(ROW()-6,"0000")) -> T10.00 | B16: 46239 | C16: =IF($B16="","",TEXT($B16,"YYYY-MM")) -> 2026-08 | D16: =IF($B16="","",YEAR($B16)) -> 2026 | E16: NBD Current | F16: Expense | G16: Food & Dining | H16: Fast food | I16: Burger King Dubai Mall | J16: Household | K16: Variable | L16: Non-Essential | M16: Card | N16: No | O16: 10 | P16: AED | Q16: =IF($B16="","",IF($P16<>"AED",0,IF($F16="Income",$O16,IF($F16="Expense",-$O16,0)))) -> -10 | S16: Yes | U16: 2026-08-05 10:47
A17: =IF($B17="","","T"&TEXT(ROW()-6,"0000")) -> T11.00 | B17: 46239 | C17: =IF($B17="","",TEXT($B17,"YYYY-MM")) -> 2026-08 | D17: =IF($B17="","",YEAR($B17)) -> 2026 | E17: NBD Current | F17: Expense | G17: Food & Dining | H17: Fast food | I17: Texas Dubai Mall | J17: Household | K17: Variable | L17: Non-Essential | M17: Card | N17: No | O17: 10 | P17: AED | Q17: =IF($B17="","",IF($P17<>"AED",0,IF($F17="Income",$O17,IF($F17="Expense",-$O17,0)))) -> -10 | S17: Yes | U17: 2026-08-05 10:48
A18: =IF($B18="","","T"&TEXT(ROW()-6,"0000")) -> T12.00 | B18: 46239 | C18: =IF($B18="","",TEXT($B18,"YYYY-MM")) -> 2026-08 | D18: =IF($B18="","",YEAR($B18)) -> 2026 | E18: NBD Current | F18: Expense | G18: Food & Dining | H18: Restaurant | I18: Team Taste Restaurant | J18: Household | K18: Variable | L18: Non-Essential | M18: Card | N18: No | O18: 31 | P18: AED | Q18: =IF($B18="","",IF($P18<>"AED",0,IF($F18="Income",$O18,IF($F18="Expense",-$O18,0)))) -> -31 | S18: Yes | U18: 2026-08-05 15:22
A19: =IF($B19="","","T"&TEXT(ROW()-6,"0000")) -> T13.00 | B19: 46239 | C19: =IF($B19="","",TEXT($B19,"YYYY-MM")) -> 2026-08 | D19: =IF($B19="","",YEAR($B19)) -> 2026 | E19: NBD Current | F19: Expense | G19: Groceries | H19: Supermarket | I19: Raya Al Talal Supermarket | J19: Household | K19: Variable | L19: Essential | M19: Card | N19: No | O19: 10.25 | P19: AED | Q19: =IF($B19="","",IF($P19<>"AED",0,IF($F19="Income",$O19,IF($F19="Expense",-$O19,0)))) -> -10.25 | S19: Yes | U19: 2026-08-05 15:23
A20: =IF($B20="","","T"&TEXT(ROW()-6,"0000")) -> T14.00 | B20: 46239 | C20: =IF($B20="","",TEXT($B20,"YYYY-MM")) -> 2026-08 | D20: =IF($B20="","",YEAR($B20)) -> 2026 | E20: FAB 4001 Current | F20: Expense | G20: Lifestyle | H20: Convenience store | I20: Asas Al Madina General | J20: Personal | K20: Variable | L20: Non-Essential | M20: Card | N20: No | O20: 14 | P20: AED | Q20: =IF($B20="","",IF($P20<>"AED",0,IF($F20="Income",$O20,IF($F20="Expense",-$O20,0)))) -> -14 | S20: Yes | U20: 2026-08-05 15:49
A21: =IF($B21="","","T"&TEXT(ROW()-6,"0000")) -> T15.00 | B21: 46240 | C21: =IF($B21="","",TEXT($B21,"YYYY-MM")) -> 2026-08 | D21: =IF($B21="","",YEAR($B21)) -> 2026 | E21: FAB 4001 Current | F21: Expense | G21: Groceries | H21: Grocery | I21: Asas Al Madina General | J21: Household | K21: Variable | L21: Essential | M21: Card | N21: No | O21: 20 | P21: AED | Q21: =IF($B21="","",IF($P21<>"AED",0,IF($F21="Income",$O21,IF($F21="Expense",-$O21,0)))) -> -20 | S21: Yes | U21: 2026-08-06 16:43
A22: =IF($B22="","","T"&TEXT(ROW()-6,"0000")) -> T16.00 | B22: 46240 | C22: =IF($B22="","",TEXT($B22,"YYYY-MM")) -> 2026-08 | D22: =IF($B22="","",YEAR($B22)) -> 2026 | E22: FAB 4002 Home Expenditure | F22: Income | G22: Salary | H22: Advance | I22: Advance salary + ticket refund profit | J22: Income | K22: Fixed | L22: Essential | M22: Bank credit | N22: Yes | O22: 4000 | P22: AED | Q22: =IF($B22="","",IF($P22<>"AED",0,IF($F22="Income",$O22,IF($F22="Expense",-$O22,0)))) -> 4000 | R22: Remaining August payday | S22: Yes | T22: AED 3,740 early salary + AED 260 profit from the ticket refund = AED 4,000, landing in FAB 4002 (the rent vault), not 4001. Counts against the 26 Aug payday. | U22: 2026-08-06 20:56
A23: =IF($B23="","","T"&TEXT(ROW()-6,"0000")) | C23: =IF($B23="","",TEXT($B23,"YYYY-MM")) | D23: =IF($B23="","",YEAR($B23)) | Q23: =IF($B23="","",IF($P23<>"AED",0,IF($F23="Income",$O23,IF($F23="Expense",-$O23,0)))) | S23: No
A24: =IF($B24="","","T"&TEXT(ROW()-6,"0000")) -> T18.00 | B24: 46241 | C24: =IF($B24="","",TEXT($B24,"YYYY-MM")) -> 2026-08 | D24: =IF($B24="","",YEAR($B24)) -> 2026 | E24: FAB 4001 Current | F24: Expense | G24: Family Support | H24: Medical support | I24: e& Money medical support | J24: Household | K24: Variable | L24: Essential | M24: Transfer | N24: No | O24: 100 | P24: AED | Q24: =IF($B24="","",IF($P24<>"AED",0,IF($F24="Income",$O24,IF($F24="Expense",-$O24,0)))) -> -100 | S24: Yes | U24: 2026-08-07 06:00
A25: =IF($B25="","","T"&TEXT(ROW()-6,"0000")) -> T19.00 | B25: 46241 | C25: =IF($B25="","",TEXT($B25,"YYYY-MM")) -> 2026-08 | D25: =IF($B25="","",YEAR($B25)) -> 2026 | E25: FAB 4001 Current | F25: Transfer Out | G25: Internal Transfer | H25: Duplicate transfer | I25: Duplicate e& Money transfer | J25: Internal | K25: Variable | L25: Essential | M25: Transfer | N25: No | O25: 100 | P25: AED | Q25: =IF($B25="","",IF($P25<>"AED",0,IF($F25="Income",$O25,IF($F25="Expense",-$O25,0)))) -> 0 | S25: Yes | T25: Receivable — refunded 11 Aug. Never an expense | U25: 2026-08-07 06:01
A26: =IF($B26="","","T"&TEXT(ROW()-6,"0000")) -> T20.00 | B26: 46245 | C26: =IF($B26="","",TEXT($B26,"YYYY-MM")) -> 2026-08 | D26: =IF($B26="","",YEAR($B26)) -> 2026 | E26: NBD Current | F26: Expense | G26: Lifestyle | H26: Unidentified card spend | I26: NBD card — merchant not identified | J26: Personal | K26: Variable | L26: Non-Essential | M26: Card | N26: No | O26: 13.5 | P26: AED | Q26: =IF($B26="","",IF($P26<>"AED",0,IF($F26="Income",$O26,IF($F26="Expense",-$O26,0)))) -> -13.5 | S26: No | T26: Identified from the NBD balance trail (15.70 recorded vs 2.20 actual). Confirm the merchant. | U26: 2026-08-11 (from balance trail)
A27: =IF($B27="","","T"&TEXT(ROW()-6,"0000")) -> T21.00 | B27: 46241 | C27: =IF($B27="","",TEXT($B27,"YYYY-MM")) -> 2026-08 | D27: =IF($B27="","",YEAR($B27)) -> 2026 | E27: FAB 4001 Current | F27: Expense | G27: Travel & Airfare | H27: Airfare | I27: Emirates ticket | J27: Household | K27: Variable | L27: Essential | M27: Card | N27: No | O27: 1430 | P27: AED | Q27: =IF($B27="","",IF($P27<>"AED",0,IF($F27="Income",$O27,IF($F27="Expense",-$O27,0)))) -> -1430 | R27: Rent refund | S27: Yes | T27: Refund of AED 1,430 expected — treated as a future inflow, not netted here | U27: 2026-08-07 15:54
A28: =IF($B28="","","T"&TEXT(ROW()-6,"0000")) -> T22.00 | B28: 46242 | C28: =IF($B28="","",TEXT($B28,"YYYY-MM")) -> 2026-08 | D28: =IF($B28="","",YEAR($B28)) -> 2026 | E28: FAB 4001 Current | F28: Expense | G28: Lifestyle | H28: Convenience store | I28: Asas Al Madina General | J28: Personal | K28: Variable | L28: Non-Essential | M28: Card | N28: No | O28: 14 | P28: AED | Q28: =IF($B28="","",IF($P28<>"AED",0,IF($F28="Income",$O28,IF($F28="Expense",-$O28,0)))) -> -14 | S28: Yes | U28: 2026-08-08 07:36
A29: =IF($B29="","","T"&TEXT(ROW()-6,"0000")) -> T23.00 | B29: 46242 | C29: =IF($B29="","",TEXT($B29,"YYYY-MM")) -> 2026-08 | D29: =IF($B29="","",YEAR($B29)) -> 2026 | E29: FAB 4001 Current | F29: Expense | G29: Lifestyle | H29: Hotel / leisure | I29: RTS Business Bay Hotel | J29: Personal | K29: Variable | L29: Non-Essential | M29: Card | N29: No | O29: 65 | P29: AED | Q29: =IF($B29="","",IF($P29<>"AED",0,IF($F29="Income",$O29,IF($F29="Expense",-$O29,0)))) -> -65 | S29: Yes | U29: 2026-08-08 15:45
A30: =IF($B30="","","T"&TEXT(ROW()-6,"0000")) -> T24.00 | B30: 46242 | C30: =IF($B30="","",TEXT($B30,"YYYY-MM")) -> 2026-08 | D30: =IF($B30="","",YEAR($B30)) -> 2026 | E30: FAB 4001 Current | F30: Expense | G30: Lifestyle | H30: Hotel / leisure | I30: RTS Business Bay Hotel | J30: Personal | K30: Variable | L30: Non-Essential | M30: Card | N30: No | O30: 47.25 | P30: AED | Q30: =IF($B30="","",IF($P30<>"AED",0,IF($F30="Income",$O30,IF($F30="Expense",-$O30,0)))) -> -47.25 | S30: Yes | U30: 2026-08-08 17:24
A31: =IF($B31="","","T"&TEXT(ROW()-6,"0000")) -> T25.00 | B31: 46242 | C31: =IF($B31="","",TEXT($B31,"YYYY-MM")) -> 2026-08 | D31: =IF($B31="","",YEAR($B31)) -> 2026 | E31: FAB 4001 Current | F31: Expense | G31: Lifestyle | H31: Hotel / leisure | I31: RTS Business Bay Hotel | J31: Personal | K31: Variable | L31: Non-Essential | M31: Card | N31: No | O31: 274.5 | P31: AED | Q31: =IF($B31="","",IF($P31<>"AED",0,IF($F31="Income",$O31,IF($F31="Expense",-$O31,0)))) -> -274.5 | S31: Yes | T31: Third charge same venue same day — AED 386.75 total on 08 Aug | U31: 2026-08-08 17:42
A32: =IF($B32="","","T"&TEXT(ROW()-6,"0000")) -> T26.00 | B32: 46242 | C32: =IF($B32="","",TEXT($B32,"YYYY-MM")) -> 2026-08 | D32: =IF($B32="","",YEAR($B32)) -> 2026 | E32: FAB 4001 Current | F32: Expense | G32: Lifestyle | H32: Convenience store | I32: Asas Al Madina General | J32: Personal | K32: Variable | L32: Non-Essential | M32: Card | N32: No | O32: 20.5 | P32: AED | Q32: =IF($B32="","",IF($P32<>"AED",0,IF($F32="Income",$O32,IF($F32="Expense",-$O32,0)))) -> -20.5 | S32: Yes | U32: 2026-08-08 20:03
A33: =IF($B33="","","T"&TEXT(ROW()-6,"0000")) -> T27.00 | B33: 46243 | C33: =IF($B33="","",TEXT($B33,"YYYY-MM")) -> 2026-08 | D33: =IF($B33="","",YEAR($B33)) -> 2026 | E33: FAB 4001 Current | F33: Expense | G33: Food & Dining | H33: Restaurant | I33: Salkara / Team Taste | J33: Household | K33: Variable | L33: Non-Essential | M33: Card | N33: No | O33: 101.5 | P33: AED | Q33: =IF($B33="","",IF($P33<>"AED",0,IF($F33="Income",$O33,IF($F33="Expense",-$O33,0)))) -> -101.5 | S33: Yes | U33: 2026-08-09 09:43
A34: =IF($B34="","","T"&TEXT(ROW()-6,"0000")) -> T28.00 | B34: 46243 | C34: =IF($B34="","",TEXT($B34,"YYYY-MM")) -> 2026-08 | D34: =IF($B34="","",YEAR($B34)) -> 2026 | E34: FAB 4001 Current | F34: Expense | G34: Lifestyle | H34: Convenience store | I34: Shams Al Qusais Grocery | J34: Personal | K34: Variable | L34: Non-Essential | M34: Card | N34: No | O34: 10 | P34: AED | Q34: =IF($B34="","",IF($P34<>"AED",0,IF($F34="Income",$O34,IF($F34="Expense",-$O34,0)))) -> -10 | S34: Yes | U34: 2026-08-09 15:37
A35: =IF($B35="","","T"&TEXT(ROW()-6,"0000")) -> T29.00 | B35: 46243 | C35: =IF($B35="","",TEXT($B35,"YYYY-MM")) -> 2026-08 | D35: =IF($B35="","",YEAR($B35)) -> 2026 | E35: FAB 4001 Current | F35: Expense | G35: Transport | H35: Fuel | I35: ENOC Site 1006 | J35: Household | K35: Variable | L35: Essential | M35: Card | N35: No | O35: 50 | P35: AED | Q35: =IF($B35="","",IF($P35<>"AED",0,IF($F35="Income",$O35,IF($F35="Expense",-$O35,0)))) -> -50 | S35: Yes | U35: 2026-08-09 15:49
A36: =IF($B36="","","T"&TEXT(ROW()-6,"0000")) -> T30.00 | B36: 46244 | C36: =IF($B36="","",TEXT($B36,"YYYY-MM")) -> 2026-08 | D36: =IF($B36="","",YEAR($B36)) -> 2026 | E36: FAB 4001 Current | F36: Expense | G36: Lifestyle | H36: Fuel / convenience | I36: Emarat Nad Al Hamar | J36: Personal | K36: Variable | L36: Non-Essential | M36: Card | N36: No | O36: 13.5 | P36: AED | Q36: =IF($B36="","",IF($P36<>"AED",0,IF($F36="Income",$O36,IF($F36="Expense",-$O36,0)))) -> -13.5 | S36: Yes | U36: 2026-08-10 07:49
A37: =IF($B37="","","T"&TEXT(ROW()-6,"0000")) -> T31.00 | B37: 46244 | C37: =IF($B37="","",TEXT($B37,"YYYY-MM")) -> 2026-08 | D37: =IF($B37="","",YEAR($B37)) -> 2026 | E37: FAB 4001 Current | F37: Expense | G37: Food & Dining | H37: Restaurant | I37: Jamahir Al Khair Restaurant | J37: Household | K37: Variable | L37: Non-Essential | M37: Card | N37: No | O37: 27 | P37: AED | Q37: =IF($B37="","",IF($P37<>"AED",0,IF($F37="Income",$O37,IF($F37="Expense",-$O37,0)))) -> -27 | S37: Yes | U37: 2026-08-10 10:37
A38: =IF($B38="","","T"&TEXT(ROW()-6,"0000")) -> T32.00 | B38: 46244 | C38: =IF($B38="","",TEXT($B38,"YYYY-MM")) -> 2026-08 | D38: =IF($B38="","",YEAR($B38)) -> 2026 | E38: FAB 4001 Current | F38: Expense | G38: Groceries | H38: Grocery | I38: Asas Al Madina General | J38: Household | K38: Variable | L38: Essential | M38: Card | N38: No | O38: 23 | P38: AED | Q38: =IF($B38="","",IF($P38<>"AED",0,IF($F38="Income",$O38,IF($F38="Expense",-$O38,0)))) -> -23 | S38: Yes | U38: 2026-08-10 13:29
A39: =IF($B39="","","T"&TEXT(ROW()-6,"0000")) -> T33.00 | B39: 46244 | C39: =IF($B39="","",TEXT($B39,"YYYY-MM")) -> 2026-08 | D39: =IF($B39="","",YEAR($B39)) -> 2026 | E39: FAB 4001 Current | F39: Expense | G39: Food & Dining | H39: Delivery | I39: Zomato | J39: Household | K39: Variable | L39: Non-Essential | M39: Card | N39: No | O39: 66.52 | P39: AED | Q39: =IF($B39="","",IF($P39<>"AED",0,IF($F39="Income",$O39,IF($F39="Expense",-$O39,0)))) -> -66.52 | S39: Yes | U39: 2026-08-10 15:51
