Workbook

Sheet Dashboard
A1: Johnny's Edge — Lifetime Finance Command Centre
A3: Controlled mirror · Expected salary is never treated as banked cash · Budget, Net Worth, Wealth Plan, Goals and the AI Advisor all recalculate from the Inputs and Recent Ledger sheets
A5: CURRENT POSITION | J5: Month | K5: Income | L5: Costs
A6: Liquid cash | B6: ='Inputs'!B14 -> 6105.64 | C6: Rent protected | D6: ='Inputs'!B31 -> 5990.45 | E6: Emergency fund | F6: ='Inputs'!B32 -> 7.67 | G6: Protection shortfall | H6: 705.76 | J6: Aug | K6: =B19 -> 2906 | L6: =C19 -> 843.28
A7: Actual | C7: Actual | E7: Actual | G7: Before salary | J7: Sep | K7: =B20 -> 7914.88 | L7: =C20 -> 3655.11
A8: Rent cheque | B8: ='Inputs'!B30 -> 11750 | C8: Projected rent money | D8: ='Monthly Plan'!D23 -> 10222.8 | E8: Current projected gap | F8: ='Monthly Plan'!D24 -> 1527.2 | G8: Actual rent gap | H8: 5759.55 | J8: Oct 1–22 | K8: =B21 -> 0 | L8: =C21 -> 13955.33
A9: Actual | C9: Before closure actions | E9: Before closure actions | G9: AED 11,750 less protected rent | J9: Rent cheque | K9: 0 | L9: 11750
A11: RENT CLOSURE ACTIONS
A12: Action | B12: Amount | C12: Deadline | D12: Evidence | E12: Action | F12: Amount | G12: Deadline | H12: Evidence
A13: Salary estimate reduction | B13: ='Rent Closure'!B8 -> 24 | C13: 46265 | D13: AED 2,906 expected; verify credit | E13: Additional income required | F13: ='Rent Closure'!B9 -> 1527.2 | G13: 46295 | H13: Banked cash only
A14: Earn additional income | B14: ='Rent Closure'!B10 -> 0 | C14: 46316 | D14: Banked cash only | E14: Survival spending cap | F14: ='Rent Closure'!B12 -> 285 | G14: 46316 | H14: AED 5/day; AED 35/week
A15: Final conditional rent gap | B15: ='Rent Closure'!B11 -> 0 | C15: 46316 | D15: Must equal zero | E15: Rent cheque | F15: ='Inputs'!B30 -> 11750 | G15: 46317 | H15: Fund by 21 Oct
A17: MONTHLY CASH FLOW TO RENT
A18: Period | B18: Income | C18: Costs before rent | D18: Rent available
A19: Aug 2026 | B19: =SUM('Monthly Plan'!B9:B10) -> 2906 | C19: ='Monthly Plan'!B21 -> 843.28 | D19: ='Monthly Plan'!B22 -> 8168.36
A20: Sep 2026 | B20: ='Monthly Plan'!C11 -> 7914.88 | C20: ='Monthly Plan'!C21 -> 3655.11 | D20: ='Monthly Plan'!C22 -> 12428.13
A21: Oct 1–22 | B21: =0 -> 0 | C21: ='Monthly Plan'!D21 -> 13955.33 | D21: ='Monthly Plan'!D23 -> 10222.8
A22: Total available for rent | D22: ='Monthly Plan'!D23 -> 10222.8
A24: CONTROL STATUS
A25: PAYDAY DAMAGE CONTROL · AED 2,906 EXPECTED
A26: Allocate: DEWA AED 713.03 from salary + AED 100.25 already above rent · Tabby AED 1,314.50 · Survival AED 160 · du/Etisalat AED 718.47. Telecom remains AED 196.46 short from salary, reduced to AED 189.19 after current loose cash.
A27: September SIP AED 462 is not funded. Total extra cash needed: AED 651.19. If unavailable, pause SIP before borrowing. Keep AED 5,990.45 rent untouched and Tabby frozen.
A29: WEALTH POSITION
A30: Metric | B30: Value | C30: Metric | D30: Value | E30: Metric | F30: Value | G30: Metric | H30: Value | J30: Metric | K30: Value
A31: Net worth | B31: ='Net Worth'!F28 -> 16053.319 | C31: Total assets | D31: ='Net Worth'!F25 -> 18740.679 | E31: Total liabilities | F31: ='Net Worth'!F27 -> 2687.36 | G31: Investments (AED) | H31: ='Net Worth'!F21 -> 12635.039 | J31: Health score | K31: ='AI Advisor'!C13 -> 35.858565
A32: Free net worth after commitments | B32: ='Net Worth'!F36 -> 9642.1787 | C32: Free cash today | D32: ='Inputs'!B43 -> 107.52 | E32: Emergency cover (months) | F32: ='Net Worth'!B46 -> 0.0011900926 | G32: Debt to assets | H32: ='Net Worth'!B42 -> 0.14339715 | J32: Grade | K32: ='AI Advisor'!E13 -> D
A33: Monthly plan surplus | B33: =Budget!B39 -> -881.89667 | C33: Savings rate achieved | D33: =Budget!B42 -> 0.083690467 | E33: Lifestyle run rate | F33: =Budget!D27 -> 3849.363 | G33: Daily burn | H33: ='Spend Analysis'!B39 -> 95.762609 | J33: Checks passing | K33: =Checks!B41 -> 30
A34: Capital at 20-year horizon | B34: ='Wealth Plan'!F38 -> 775778.83 | C34: In today's money | D34: ='Wealth Plan'!G38 -> 473435.28 | E34: Independence target | F34: ='Wealth Plan'!B54 -> 1933463 | G34: Years to independence | H34: ='Wealth Plan'!B55 -> beyond horizon | J34: Checks expected | K34: =Checks!C41 -> 30
A36: WHAT TO DO NEXT — TOP ACTIONS FROM THE AI ADVISOR
A37: ='AI Advisor'!A47 -> Health score 36 out of 100, grade D. Net worth is AED 16,053.32, of which AED 12,635.04 actually compounds. The balance sheet is not the problem — the calendar is. AED 5,759.55 of rent still has to be found before 21 Oct, AED 651.59 before 15 Sep, and free cash outside rent and emergency stands at AED 107.52. Do four things in order: hold the rent ring-fence, close the September gap by earning or by pausing the SIP, let the Tabby minimums run to zero by 3 Nov without ever paying a fee, and start accruing rent monthly so October 2027 is a transfer instead of a crisis. Then, and only then, raise the SIP.
A39: This dashboard now mirrors two things at once: the ninety-day survival plan above, and the long-term wealth position below. Read the top half when deciding what to do this week, and the bottom half when deciding whether the week mattered.

Sheet AI Advisor
A1: AI Advisor — Live Recommendations
A3: Every recommendation below is wired to a live condition in this workbook. Change a balance on Inputs or add a line to the ledger and the status column re-decides itself — an item closes when the data says it is closed, not when someone ticks it off. Impact is the dirham value of acting, stated per month unless the note says otherwise.
A5: HEALTH SCORE
A6: # | B6: Component | C6: Score | D6: Weight | E6: Weighted | H6: How it is measured
A7: 1 | B7: Liquidity — free cash against one month of essentials | C7: =MIN(100,MAX(0,IF(Budget!B17=0,0,'Inputs'!B43/Budget!B17)*100)) -> 1.6683019 | D7: 0.2 | E7: =C7*D7 -> 0.33366038 | H7: Free cash outside rent and emergency, divided by monthly essentials, capped at 100.
A8: 2 | B8: Emergency cover — months held against the six-month target | C8: =MIN(100,MAX(0,IF(Budget!B17=0,0,'Inputs'!B32/(Budget!B17*'FX & Assumptions'!B33))*100)) -> 0.019834877 | D8: 0.2 | E8: =C8*D8 -> 0.0039669753 | H8: Emergency fund against six months of essentials.
A9: 3 | B9: Debt — exposure against total assets | C9: =MIN(100,MAX(0,(1-IF('Net Worth'!F25=0,1,'Net Worth'!F27/'Net Worth'!F25))*100)) -> 85.660285 | D9: 0.15 | E9: =C9*D9 -> 12.849043 | H9: One hundred means debt free.
A10: 4 | B10: Savings rate — achieved against target | C10: =MIN(100,MAX(0,IF('FX & Assumptions'!B30=0,0,Budget!B42/'FX & Assumptions'!B30)*100)) -> 41.845233 | D10: 0.2 | E10: =C10*D10 -> 8.3690467 | H10: Investing and emergency top-ups against the target savings rate.
A11: 5 | B11: Budget balance — does the plan fit the salary | C11: =IF(Budget!B39>=0,100,MAX(0,100+Budget!B39/MAX(1,Budget!B8)*100)) -> 88.857738 | D11: 0.15 | E11: =C11*D11 -> 13.328661 | H11: One hundred when the plan balances; falls as the deficit widens.
A12: 6 | B12: Spending discipline — run rate against plan | C12: =MIN(100,MAX(0,IF(Budget!D27=0,100,Budget!B27/Budget!D27*100))) -> 9.7418716 | D12: 0.1 | E12: =C12*D12 -> 0.97418716 | H12: Planned lifestyle spending divided by the actual lifestyle run rate.
B13: FINANCIAL HEALTH SCORE | C13: =SUM(E7:E12) -> 35.858565 | D13: =SUM(D7:D12) -> 1 | E13: =IF(C13>=80,"A",IF(C13>=65,"B",IF(C13>=50,"C",IF(C13>=35,"D","E")))) -> D | H13: Weights are levers — adjust them if you disagree with the emphasis. The grade in column E is the honest headline: an E or a D means the next ninety days are about survival, not strategy.
A15: URGENT — DO THIS WEEK
A16: # | B16: Recommendation | C16: Status | D16: Effort | E16: Impact (AED) | F16: Priority | G16: By when | H16: Why this, and why now
A17: 1 | B17: Bank the AED 189.19 bills-and-survival gap before 15 Sep | C17: =IF('Inputs'!B51>0.01,"OPEN","CLOSED") -> OPEN | D17: High | E17: ='Inputs'!B51 -> 189.19 | F17: =IF(E17>=500,"1 — Critical",IF(E17>=100,"2 — High",IF(E17>=25,"3 — Useful","4 — Housekeeping"))) -> 2 — High | G17: 46280 | H17: Confirmed bills plus the survival allowance exceed loose cash plus the expected payday. This is the one number that decides whether September is calm or improvised. Earn it, or pause the SIP — in that order.
A18: 2 | B18: Do not touch the protected rent in FAB 4002 | C18: =IF('Inputs'!B31>0,"IN FORCE","Released") -> IN FORCE | D18: None | E18: ='Inputs'!B31 -> 5990.45 | F18: =IF(E18>=500,"1 — Critical",IF(E18>=100,"2 — High",IF(E18>=25,"3 — Useful","4 — Housekeeping"))) -> 1 — Critical | G18: 46316 | H18: FAB 4002 shows AED 6,090.70 but only AED 100.25 of it is yours to spend. Treating the account balance as available is the single most likely way this plan fails.
A19: 3 | B19: Let the AED 1,314.50 Tabby autopay run on 3 Sep — do not pay the full statement | C19: =IF('Inputs'!B36>0,"SCHEDULED","Done") -> SCHEDULED | D19: None | E19: ='Inputs'!B37-'Inputs'!B36 -> 657.53 | F19: =IF(E19>=500,"1 — Critical",IF(E19>=100,"2 — High",IF(E19>=25,"3 — Useful","4 — Housekeeping"))) -> 1 — Critical | G19: 46268 | H19: Paying the full August statement costs AED 657.53 more in the month you can least afford it, and saves no fee at all. The Debt Plan proves it.
A20: 4 | B20: Confirm the AED 2,906 salary actually credits on 26 Aug | C20: =IF('Inputs'!C22="Estimated","UNCONFIRMED","Confirmed") -> UNCONFIRMED | D20: Low | E20: ='Inputs'!B22 -> 2906 | F20: =IF(E20>=500,"1 — Critical",IF(E20>=100,"2 — High",IF(E20>=25,"3 — Useful","4 — Housekeeping"))) -> 1 — Critical | G20: 46260 | H20: Every downstream number in this workbook assumes it arrives. Until it is on a statement it is a hope, and the model deliberately refuses to call it cash.
A22: SPENDING — WHERE THE MONEY IS LEAKING
A23: # | B23: Recommendation | C23: Status | D23: Effort | E23: Impact (AED) | F23: Priority | G23: By when | H23: Why this, and why now
A24: 1 | B24: Bring dining back to the plan | C24: =IF(Budget!D21>Budget!B21,"OVER PLAN","OK") -> OVER PLAN | D24: Medium | E24: =MAX(0,Budget!D21-Budget!B21) -> 839.30101 | F24: =IF(E24>=500,"1 — Critical",IF(E24>=100,"2 — High",IF(E24>=25,"3 — Useful","4 — Housekeeping"))) -> 1 — Critical | G24: 46295 | H24: Dining is the largest genuinely controllable category in the ledger. The impact column is the monthly saving from simply hitting the number already written in the Budget.
A25: 2 | B25: Cancel one of the two telecom lines | C25: =IF(AND('Inputs'!B34>0,'Inputs'!B35>0),"TWO LINES ACTIVE","Consolidated") -> TWO LINES ACTIVE | D25: Low | E25: =MIN('Inputs'!B34,'Inputs'!B35) -> 323.95 | F25: =IF(E25>=500,"1 — Critical",IF(E25>=100,"2 — High",IF(E25>=25,"3 — Useful","4 — Housekeeping"))) -> 2 — High | G25: 46295 | H25: du and Etisalat are both being paid every month for one person. Cancelling the smaller line is a permanent saving that requires no willpower at all — the best kind.
A26: 3 | B26: Bring the daily burn under the damage-control cap | C26: =IF('Spend Analysis'!B31>'Spend Analysis'!C31,"ABOVE CAP","WITHIN CAP") -> ABOVE CAP | D26: High | E26: =MAX(0,('Spend Analysis'!B39-'Spend Analysis'!C39)*30.44) -> 2762.8138 | F26: =IF(E26>=500,"1 — Critical",IF(E26>=100,"2 — High",IF(E26>=25,"3 — Useful","4 — Housekeeping"))) -> 1 — Critical | G26: 46290 | H26: The plan caps living costs at AED 5 a day. The confirmed ledger shows day-to-day living running at a large multiple of that. This gap, compounded over eight weeks, is roughly the size of the rent shortfall.
A27: 4 | B27: Kill the Netflix retry | C27: =IF('Obligations'!C18>0,"OPEN","Closed") -> OPEN | D27: None | E27: ='Obligations'!C18 -> 35 | F27: =IF(E27>=500,"1 — Critical",IF(E27>=100,"2 — High",IF(E27>=25,"3 — Useful","4 — Housekeeping"))) -> 3 — Useful | G27: 46266 | H27: The charge was declined, not paid. Cancel it properly rather than leaving it to retry against an account that is holding rent money.
A28: 5 | B28: Stop paying transfer fees | C28: =IF(Budget!D25>0,"LEAKING","Clean") -> LEAKING | D28: Low | E28: =Budget!D25 -> 0.64850435 | F28: =IF(E28>=500,"1 — Critical",IF(E28>=100,"2 — High",IF(E28>=25,"3 — Useful","4 — Housekeeping"))) -> 4 — Housekeeping | G28: 46295 | H28: Small, but it is pure leakage: a fee buys nothing. Batch transfers instead of moving money several times a week.
A29: 6 | B29: Give the AED 14 unreconciled movement a name | C29: =IF(COUNTIFS('Recent Ledger'!$I$6:$I$101,"Unreconciled")>0,"OPEN","Clean") -> OPEN | D29: Low | E29: =SUMIFS('Recent Ledger'!$D$6:$D$101,'Recent Ledger'!$I$6:$I$101,"Unreconciled") -> 64 | F29: =IF(E29>=500,"1 — Critical",IF(E29>=100,"2 — High",IF(E29>=25,"3 — Useful","4 — Housekeeping"))) -> 3 — Useful | G29: 46272 | H29: A control item rather than a money item. A ledger where every dirham has a merchant is a ledger you can trust when it matters.
A31: STRUCTURE — STOP THE CRISIS REPEATING
A32: # | B32: Recommendation | C32: Status | D32: Effort | E32: Impact (AED) | F32: Priority | G32: By when | H32: Why this, and why now
A33: 1 | B33: Start a monthly rent accrual | C33: =IF('Net Worth'!F34>0.01,"NOT STARTED","Funded") -> NOT STARTED | D33: Medium | E33: ='FX & Assumptions'!B29 -> 3916.6667 | F33: =IF(E33>=500,"1 — Critical",IF(E33>=100,"2 — High",IF(E33>=25,"3 — Useful","4 — Housekeeping"))) -> 1 — Critical | G33: 46327 | H33: The rent cheque is not an emergency, it is a subscription that arrives on a known date. Moving the monthly accrual into FAB 4002 on payday converts every future cheque from a crisis into a transfer. This is the highest-value structural change in the workbook.
A34: 2 | B34: Confirm how many rent cheques the lease actually requires | C34: =IF('FX & Assumptions'!B27=4,"ASSUMED — CONFIRM","Confirmed") -> ASSUMED — CONFIRM | D34: None | E34: ='FX & Assumptions'!B28 -> 47000 | F34: =IF(E34>=500,"1 — Critical",IF(E34>=100,"2 — High",IF(E34>=25,"3 — Useful","4 — Housekeeping"))) -> 1 — Critical | G34: 46272 | H34: The whole rent accrual, the Budget essentials ratio and the emergency-fund target all rest on four cheques a year. It is an assumption, not a fact, and it is one phone call to settle.
A35: 3 | B35: Get the emergency fund to AED 1,000 | C35: =IF('Inputs'!B32<1000,"UNFUNDED","Milestone reached") -> UNFUNDED | D35: Medium | E35: =MAX(0,1000-'Inputs'!B32) -> 992.33 | F35: =IF(E35>=500,"1 — Critical",IF(E35>=100,"2 — High",IF(E35>=25,"3 — Useful","4 — Housekeeping"))) -> 1 — Critical | G35: 46477 | H35: AED 7.67 is not a buffer. Until there is a real one, every unexpected cost lands on the card or on the rent money.
A36: 4 | B36: Move to a single spending account with a weekly allowance | C36: ="RECOMMENDED" -> RECOMMENDED | D36: Low | E36: =0 -> 0 | F36: =IF(E36>=500,"1 — Critical",IF(E36>=100,"2 — High",IF(E36>=25,"3 — Useful","4 — Housekeeping"))) -> 4 — Housekeeping | G36: 46296 | H36: The ledger shows constant small transfers from 4002 into 4001. Each one is a decision, and each one erodes the ring-fence. One weekly transfer, then spend only what landed.
A38: INVESTING — THE PART THAT COMPOUNDS
A39: # | B39: Recommendation | C39: Status | D39: Effort | E39: Impact (AED) | F39: Priority | G39: By when | H39: Why this, and why now
A40: 1 | B40: Sweep the idle rupee cash into the next SIP | C40: =IF('Net Worth'!F19>1,"IDLE","Swept") -> IDLE | D40: None | E40: ='Net Worth'!F19 -> 14.970572 | F40: =IF(E40>=500,"1 — Critical",IF(E40>=100,"2 — High",IF(E40>=25,"3 — Useful","4 — Housekeeping"))) -> 4 — Housekeeping | G40: 46275 | H40: Settlement cash sitting in the broker account earns nothing. It is small, but sweeping it costs nothing and is the only free money in the file.
A41: 2 | B41: Reduce single-fund-house concentration | C41: =IF('Investments'!B16>0.8,"CONCENTRATED","Diversified") -> CONCENTRATED | D41: Medium | E41: =MAX(0,('Investments'!B16-0.8)*'Investments'!E12*'FX & Assumptions'!B7) -> 1456.9714 | F41: =IF(E41>=500,"1 — Critical",IF(E41>=100,"2 — High",IF(E41>=25,"3 — Useful","4 — Housekeeping"))) -> 1 — Critical | G41: 46477 | H41: Almost the entire mutual-fund portfolio sits with one fund house. That is an operational risk as much as a market one. Direct future SIP instalments elsewhere rather than selling — no exit load, no capital gains event.
A42: 3 | B42: Do not pause the SIP unless the September gap is still open on 8 Sep | C42: =IF('Inputs'!B51>0.01,"CONDITIONAL","Safe to continue") -> CONDITIONAL | D42: None | E42: ='Inputs'!B39 -> 462.4 | F42: =IF(E42>=500,"1 — Critical",IF(E42>=100,"2 — High",IF(E42>=25,"3 — Useful","4 — Housekeeping"))) -> 2 — High | G42: 46273 | H42: A paused SIP is cheap to restart; a missed rent cheque is not. But pausing early, when the gap might still be closed by earning, gives up compounding for nothing. Decide on 8 Sep with real balances, not on 26 Aug with estimates.
A43: 4 | B43: Review the 41 open Amana positions | C43: =IF('Investments'!B25<0,"FLOATING LOSS","In profit") -> FLOATING LOSS | D43: Medium | E43: =('Investments'!B26+'Investments'!B27)*-1*'FX & Assumptions'!B9 -> 75.176075 | F43: =IF(E43>=500,"1 — Critical",IF(E43>=100,"2 — High",IF(E43>=25,"3 — Useful","4 — Housekeeping"))) -> 3 — Useful | G43: 46295 | H43: Forty-one open positions on an account worth under AED 3,200 is a lot of moving parts, and the statement shows floating and overnight fees quietly working against you. Fewer, larger, longer-held positions would cost less to carry.
A44: 5 | B44: Raise the SIP by 10% every year, automatically | C44: =IF('FX & Assumptions'!B32>0,"IN PLAN","Not set") -> IN PLAN | D44: None | E44: ='Wealth Plan'!H45 -> 394157.35 | F44: =IF(E44>=500,"1 — Critical",IF(E44>=100,"2 — High",IF(E44>=25,"3 — Useful","4 — Housekeeping"))) -> 1 — Critical | G44: 46388 | H44: The impact column is what the step-up is worth at the twenty-year horizon compared with a flat contribution. It costs nothing today because the increase comes out of next year's raise.
A46: THE ONE-PARAGRAPH VERDICT
A47: ="Health score "&TEXT(C13,"0")&" out of 100, grade "&E13&". Net worth is AED "&TEXT('Net Worth'!F28,"#,##0.00")&", of which AED "&TEXT('Net Worth'!F21,"#,##0.00")&" actually compounds. The balance sheet is not the problem — the calendar is. AED "&TEXT('Net Worth'!F34,"#,##0.00")&" of rent still has to be found before 21 Oct, AED "&TEXT('Inputs'!B53,"#,##0.00")&" before 15 Sep, and free cash outside rent and emergency stands at AED "&TEXT('Inputs'!B43,"#,##0.00")&". Do four things in order: hold the rent ring-fence, close the September gap by earning or by pausing the SIP, let the Tabby minimums run to zero by 3 Nov without ever paying a fee, and start accruing rent monthly so October 2027 is a transfer instead of a crisis. Then, and only then, raise the SIP." -> Health score 36 out of 100, grade D. Net worth is AED 16,053.32, of which AED 12,635.04 actually compounds. The balance sheet is not the problem — the calendar is. AED 5,759.55 of rent still has to be found before 21 Oct, AED 651.59 before 15 Sep, and free cash outside rent and emergency stands at AED 107.52. Do four things in order: hold the rent ring-fence, close the September gap by earning or by pausing the SIP, let the Tabby minimums run to zero by 3 Nov without ever paying a fee, and start accruing rent monthly so October 2027 is a transfer instead of a crisis. Then, and only then, raise the SIP.

Sheet Inputs
A1: Johnny's Edge — Authoritative Inputs
A3: As of 25 Aug 2026 · Confirmed balances are separated from estimates. Salary AED 2,906 is expected, not banked.
A5: CURRENT LIQUID BALANCES — CONFIRMED ACTUAL
A6: Item | B6: Amount | C6: Currency | D6: Status | E6: As of | F6: Audit note
A7: FAB 4001 | B7: 3.45 | C7: AED | D7: Actual | E7: 46259.275 | F7: Confirmed FAB app/SMS balance after AED 13.50 ENOC purchase
A8: FAB 4002 | B8: 6090.7 | C8: AED | D8: Actual | E8: 46257.901 | F8: Confirmed FAB app/SMS balance; contains AED 5,990.45 rent plus only AED 100.25 toward DEWA
A9: FAB emergency | B9: 7.67 | C9: AED | D9: Actual | E9: 46259.482 | F9: Confirmed FAB app emergency-fund balance; do not spend
A10: NBD current | B10: 0.2 | C10: AED | D10: Actual | E10: 46251.635 | F10: Confirmed NBD card-linked balance after AED 2 SRN Supermarket purchase
A11: NBD Plus Saver | B11: 2.73 | C11: AED | D11: Last reported | E11: 46248 | F11: NBD Plus Saver last reported; refresh required if changed
A12: Tabby Cash | B12: 0.89 | C12: AED | D12: Last reported | E12: 46248 | F12: Tabby Cash wallet; separate from Tabby Card borrowing
A13: Cash/Wio | B13: 0 | C13: AED | D13: Actual | E13: 46259 | F13: No other cash balance reported
A14: TOTAL LIQUID CASH | B14: =SUM(B7:B13) -> 6105.64 | C14: AED | D14: Formula | E14: 46246 | F14: Formula check: AED 6,105.64 = FAB 6,101.82 + NBD 2.93 + Tabby Cash 0.89
A16: INCOME, REFUNDS AND TIMING
A17: Driver | B17: Amount | C17: Status | D17: Expected date | E17: Treatment | F17: Audit note
A18: Normal monthly salary | B18: 7914.88 | C18: Actual baseline | D18: 46260 | E18: Salary | F18: July salary baseline
A19: Two-ticket salary recovery | B19: 3740 | C19: Actual | D19: 46241 | E19: Already in cash | F19: Two × AED 1,870 deducted from salary; principal portion of AED 4,000 received
A20: Two-ticket profit | B20: 260 | C20: Actual | D20: 46241 | E20: Already in cash | F20: AED 4,000 received less AED 3,740 salary deduction
A21: Third-ticket salary recovery | B21: 1540 | C21: Actual | D21: 46246 | E21: Already in cash | F21: AED 1,540 salary advance received on 12 Aug; removed from 26 Aug receivables
A22: Remaining payday cash | B22: 2906 | C22: Estimated | D22: 46260 | E22: Expected inflow | F22: AED 2,906 expected 26 Aug; do not count until credited
A23: Separate additional income | B23: 0 | C23: None | D23: 46260 | E23: No separate inflow | F23: AED 8,500 estimate already includes ticket profits
A24: Prior-month salary received | B24: 1430 | C24: Actual | D24: 46246 | E24: Allocate to rent | F24: Separate from the coming AED 8,500 salary cycle
A25: Coming salary-cycle total | B25: 8476 | C25: Estimated target | D25: 46260 | E25: Projection | F25: AED 5,570 already received plus approximately AED 2,906 expected
A26: Third-ticket profit | B26: 30 | C26: Actual | D26: 46246 | E26: Already in cash | F26: AED 30 ticket profit received on 12 Aug; removed from 26 Aug receivables
A27: Current expected salary-cycle income | B27: =SUM(B19:B22)+B26 -> 8476 | C27: Formula | D27: 46260 | E27: Projection | F27: Formula: AED 5,570 already received + AED 2,906 expected = AED 8,476 cycle
A28: OBLIGATIONS AND CONTROL ASSUMPTIONS
A29: Item | B29: Amount | C29: Status | D29: Date / cadence | E29: Rule | F29: Audit note
A30: October rent cheque | B30: 11750 | C30: Actual | D30: 46317 | E30: Must be fully funded by 21 Oct | F30: 26 Oct salary is too late
A31: Rent protected now | B31: 5990.45 | C31: Actual | D31: 46246 | E31: Do not spend | F31: True protected rent after excluding AED 1,020.25 required for bills and living
A32: Emergency fund | B32: 7.67 | C32: Actual | D32: 46245 | E32: Do not spend | F32: Next milestone AED 1,000
A33: DEWA monthly baseline | B33: 813.28 | C33: Actual bill | D33: 46265 | E33: Pay by due date | F33: Actual August DEWA bill supplied 25 Aug; replaces AED 793.42 estimate
A34: du recurring baseline | B34: 590.98 | C34: Estimated | D34: 46268 | E34: Monthly | F34: September estimate; replace with actual du bill when generated
A35: Etisalat recurring baseline | B35: 323.95 | C35: Estimated | D35: 46268 | E35: Monthly | F35: September estimate; replace with actual Etisalat bill when generated
A36: Tabby no-fee minimum | B36: 1314.5 | C36: Actual due | D36: 46268 | E36: Autopay / no-fee minimum | F36: Confirmed August Tabby amount due; card must remain frozen
A37: Tabby full statement | B37: 1972.03 | C37: Actual statement | D37: 46268 | E37: Optional full statement | F37: Do not choose if it compromises rent or essential bills
A38: Tabby outstanding exposure | B38: 2687.36 | C38: Actual confirmed exposure | D38: 46298 | E38: Card frozen | F38: AED 1,972.03 August statement + AED 715.33 September statement
A39: September SIP funding | B39: 462.4 | C39: Estimated | D39: 46275 | E39: Keep active | F39: ₹12,000 at last confirmed transfer rate
A40: ICICI post-Aug SIP cash | B40: 388.51 | C40: Actual | D40: 46244 | E40: INR | F40: August four SIPs completed
A41: Living cap to rent cheque | B41: 285 | C41: Control cap | D41: 46316 | E41: AED 5/day; AED 35/week | F41: AED 5/day or AED 35/week through 21 Oct; AED 160 reserved first through 25 Sep
... A43: Current loose cash outside rent/emergency | B43: 107.52 | C43: Actual | D43: 46259.315 | E43: Protected calculation | F43: AED 6,105.64 liquidity less AED 5,990.45 rent and AED 7.67 emergency
A44: ="Extra cash required before 15 Sep: AED "&TEXT(B53,"#,##0.00")&" — AED "&TEXT(B51,"#,##0.00")&" to close the bills-and-survival gap plus AED "&TEXT(B52,"#,##0.00")&" to fund the 10 Sep Nippon SIP. Bank it as real cash or pause the SIP; never take it from the AED "&TEXT(B31,"#,##0.00")&" protected rent or from the emergency fund." -> Extra cash required before 15 Sep: AED 651.59 — AED 189.19 to close the bills-and-survival gap plus AED 462.40 to fund the 10 Sep Nippon SIP. Bank it as real cash or pause the SIP; never take it from the AED 5,990.45 protected rent or from the emergency fund.
...

Sheet FX & Assumptions
A1: Rates, Returns and Planning Assumptions
A3: Every lever the rest of the workbook depends on lives here. Blue figures on a yellow fill are the only cells meant to be edited by hand; black figures are calculated. Change a lever here and Budget, Net Worth, Wealth Plan, Goals and AI Advisor all move together.
A5: CURRENCY
A6: Assumption | B6: Value | C6: Unit | D6: Basis | E6: Type | F6: Note
A7: AED per INR | B7: 0.0385333 | C7: AED / INR | D7: Derived from the last confirmed SIP transfer | E7: Lever | F7: AED 462.40 funded INR 12,000 on 10 Aug 2026, so 462.40 / 12,000 = 0.0385333. Refresh this whenever a new transfer settles at a different rate.
A8: INR per AED | B8: =IF(B7=0,0,1/B7) -> 25.95158 | C8: INR / AED | D8: Reciprocal of the row above | E8: Formula | F8: Roughly INR 25.95 per dirham at the last confirmed transfer rate.
A9: AED per USD | B9: 3.6725 | C9: AED / USD | D9: UAE dirham peg to the US dollar | E9: Lever | F9: The dirham has been pegged at 3.6725 since 1997; treat as fixed unless the peg changes.
A10: USD per AED | B10: =IF(B9=0,0,1/B9) -> 0.27229408 | C10: USD / AED | D10: Reciprocal of the row above | E10: Formula | F10: Used to read the Amana statement back into dirhams.
A12: RETURN, INFLATION AND RISK ASSUMPTIONS
A13: Assumption | B13: Value | C13: Unit | D13: Basis | E13: Type | F13: Note
A14: Indian equity mutual funds — expected return | B14: 0.11 | C14: p.a. nominal | D14: Long-run planning assumption | E14: Lever | F14: Nominal INR return before currency effects. Deliberately below the trailing returns shown on the Investments sheet: a snapshot gain is not a forecast.
A15: Global equity (Amana) — expected return | B15: 0.08 | C15: p.a. nominal | D15: Long-run planning assumption | E15: Lever | F15: Broad developed-market equity assumption in USD.
A16: Cash and savings — expected return | B16: 0.02 | C16: p.a. nominal | D16: UAE savings account range | E16: Lever | F16: FAB and NBD balances earn close to nothing; 2% is generous.
A17: Silver / commodity — expected return | B17: 0.05 | C17: p.a. nominal | D17: Long-run planning assumption | E17: Lever | F17: Applies to the Nippon Silver ETF FoF holding only.
A18: UAE inflation | B18: 0.025 | C18: p.a. | D18: Planning assumption | E18: Lever | F18: Used to restate the Wealth Plan into today's money.
A19: Scenario adjustment to returns | B19: 0 | C19: p.a. | D19: Owner-set stress lever | E19: Lever | F19: Set to 0 for the base case, -0.03 for a bear case, +0.02 for a bull case. Applies to every growth assumption in the Wealth Plan.
A20: Blended portfolio planning return | B20: =IF('Investments'!B50=0,B14,(('Investments'!B43+'Investments'!B44+'Investments'!B45+'Investments'!B46)*B14+'Investments'!B47*B17+'Investments'!B48*B15+'Investments'!B49*B16)/'Investments'!B50)+B19 -> 0.10161181 | C20: p.a. nominal | D20: Weighted by the asset-allocation table on Investments | E20: Formula | F20: Each sleeve is weighted by its present value at its own expected return: Indian equity funds at the equity rate, the silver holding at the commodity rate, Amana at the global rate and idle broker cash at the cash rate. The scenario adjustment is then added.
A21: Real (after-inflation) planning return | B21: =(1+B20)/(1+B18)-1 -> 0.074743227 | C21: p.a. real | D21: Blended return deflated by inflation | E21: Formula | F21: The number that actually matters for buying power.
A23: INCOME, HOUSING AND SAVINGS ASSUMPTIONS
A24: Assumption | B24: Value | C24: Unit | D24: Basis | E24: Type | F24: Note
A25: Net monthly salary | B25: ='Inputs'!B18 -> 7914.88 | C25: AED | D25: Inputs sheet, July salary baseline | E25: Formula | F25: Linked, not typed. Update the baseline on Inputs and every sheet follows.
A26: Annual salary increment | B26: 0.04 | C26: p.a. | D26: Planning assumption | E26: Lever | F26: Applied from the first full plan year onward.
A27: Rent cheques per year | B27: 4 | C27: cheques | D27: ASSUMPTION — CONFIRM AGAINST THE LEASE | E27: Lever | F27: The lease schedule in this file shows one cheque of AED 11,750 due 22 Oct 2026 but not the cadence. Four cheques a year is the common Dubai arrangement and is what the monthly rent accrual on Budget uses. If the real schedule is different, change this one cell.
A28: Annual rent | B28: ='Inputs'!B30*B27 -> 47000 | C28: AED | D28: Cheque value times cheques per year | E28: Formula | F28: Drives the monthly rent accrual used in the Budget.
A29: Monthly rent accrual | B29: =B28/12 -> 3916.6667 | C29: AED | D29: Annual rent spread evenly | E29: Formula | F29: Setting money aside every month is what turns the next cheque from a crisis into a transfer.
A30: Target savings rate | B30: 0.2 | C30: of net income | D30: Wealth-building target | E30: Lever | F30: Everything invested plus emergency-fund top-ups, as a share of net income.
A31: Current monthly SIP | B31: ='Inputs'!B39 -> 462.4 | C31: AED | D31: Inputs sheet | E31: Formula | F31: INR 12,000 at the last confirmed transfer rate.
A32: Annual SIP step-up | B32: 0.1 | C32: p.a. | D32: Wealth-building lever | E32: Lever | F32: Raising the SIP by 10% a year is the single highest-leverage habit in this plan; the Wealth Plan sensitivity block prices it.
A33: Emergency fund target | B33: 6 | C33: months of essential spend | D33: Standard planning rule | E33: Lever | F33: Measured against the essential subtotal on the Budget sheet.
A35: LEDGER WINDOW AND PLAN HORIZON
A36: Assumption | B36: Value | C36: Unit | D36: Basis | E36: Type | F36: Note
A37: Ledger first transaction | B37: =MIN('Recent Ledger'!$A$6:$A$101) -> 46237.472 | C37: date | D37: Recent Ledger | E37: Formula | F37: Earliest confirmed transaction in the ledger.
A38: Ledger last transaction | B38: =MAX('Recent Ledger'!$A$6:$A$101) -> 46259.275 | C38: date | D38: Recent Ledger | E38: Formula | F38: Latest confirmed transaction in the ledger.
A39: Days covered by the ledger | B39: =INT(B38)-INT(B37)+1 -> 23 | C39: days | D39: Inclusive day count | E39: Formula | F39: The ledger is a partial month, so actuals are scaled to a monthly run rate before they are compared with the plan.
A40: Run-rate factor to a full month | B40: =IF(B39=0,0,30.44/B39) -> 1.3234783 | C40: x | D40: Average month length divided by days covered | E40: Formula | F40: Multiply any ledger actual by this to get a monthly run rate.
A41: Plan start | B41: 46266 | C41: date | D41: First full month of the plan | E41: Lever | F41: The Wealth Plan projects forward from this date.
A42: Plan horizon | B42: 20 | C42: years | D42: Owner-set | E42: Lever | F42: Length of the projection on the Wealth Plan sheet.
A44: Assumption discipline: a lever is a number this workbook cannot prove. Every one of them is on this sheet, in blue on yellow, with its basis written next to it. Nothing else in the file hardcodes a rate or a return. The two levers most likely to be wrong are rent cheques per year and the AED/INR rate — confirm both against the lease and the next transfer receipt.

Sheet Budget
A1: Monthly Budget — Plan against Reality
A3: Column B is the plan. Column C is what the confirmed ledger actually shows for 3–25 Aug 2026. Column D scales that partial month to a full-month run rate so the two are comparable. A red variance means the run rate is above plan.
A5: MONTHLY INCOME
A6: Line | B6: Monthly plan | C6: Ledger actual 3–25 Aug | D6: Monthly run rate | E6: Variance vs plan | F6: % of income | G6: Priority | H6: Note
A7: Net salary | B7: ='FX & Assumptions'!B25 -> 7914.88 | C7: 0 | D7: =C7*'FX & Assumptions'!$B$40 -> 0 | E7: =D7-B7 -> -7914.88 | F7: =IF($B$8=0,0,B7/$B$8) -> 1 | G7: Core | H7: July baseline. The AED 2,906 expected on 26 Aug is the remainder of this month's cycle, not an extra month of pay.
A8: TOTAL MONTHLY INCOME | B8: =B7 -> 7914.88 | C8: =C7 -> 0 | D8: =D7 -> 0 | F8: =IF(B8=0,0,B8/B8) -> 1 | G8: Core | H8: Side income from ticket dealing is treated as one-off recovery, not salary, so it never inflates the plan.
A10: ESSENTIAL — THE BILLS THAT KEEP THE LIGHTS ON
A11: Line | B11: Monthly plan | C11: Ledger actual 3–25 Aug | D11: Monthly run rate | E11: Variance vs plan | F11: % of income | G11: Priority | H11: Note
A12: Rent accrual | B12: ='FX & Assumptions'!B29 -> 3916.6667 | C12: 0 | D12: =C12*'FX & Assumptions'!$B$40 -> 0 | E12: =D12-B12 -> -3916.6667 | F12: =IF($B$8=0,0,B12/$B$8) -> 0.49484852 | G12: Critical | H12: The rent cheque is not a surprise, it is a subscription. Accruing it monthly is what removes the October panic permanently. No ledger line exists because nothing has been set aside monthly so far.
A13: Utilities & Telecom | B13: ='Inputs'!B33+'Inputs'!B34+'Inputs'!B35 -> 1728.21 | C13: =SUMIFS('Recent Ledger'!$D$6:$D$101,'Recent Ledger'!$I$6:$I$101,$A13,'Recent Ledger'!$J$6:$J$101,1) -> 914.93 | D13: =C13*'FX & Assumptions'!$B$40 -> 1210.89 | E13: =D13-B13 -> -517.32003 | F13: =IF($B$8=0,0,B13/$B$8) -> 0.21834949 | G13: Critical | H13: DEWA AED 813.28 + du AED 590.98 + Etisalat AED 323.95. Two telecom lines for one person is the most obvious fixed-cost cut available.
A14: Groceries | B14: 450 | C14: =SUMIFS('Recent Ledger'!$D$6:$D$101,'Recent Ledger'!$I$6:$I$101,$A14,'Recent Ledger'!$J$6:$J$101,1) -> 280.53 | D14: =C14*'FX & Assumptions'!$B$40 -> 371.27536 | E14: =D14-B14 -> -78.724643 | F14: =IF($B$8=0,0,B14/$B$8) -> 0.056854937 | G14: Essential | H14: Cooking at home is the cheapest lever that does not require earning more.
A15: Fuel & Transport | B15: 250 | C15: =SUMIFS('Recent Ledger'!$D$6:$D$101,'Recent Ledger'!$I$6:$I$101,$A15,'Recent Ledger'!$J$6:$J$101,1) -> 300.52 | D15: =C15*'FX & Assumptions'!$B$40 -> 397.73169 | E15: =D15-B15 -> 147.73169 | F15: =IF($B$8=0,0,B15/$B$8) -> 0.031586076 | G15: Essential | H15: Fuel and Metro. Work-essential; protect this before cutting anything else.
A16: Family & Support | B16: 100 | C16: =SUMIFS('Recent Ledger'!$D$6:$D$101,'Recent Ledger'!$I$6:$I$101,$A16,'Recent Ledger'!$J$6:$J$101,1) -> 142.97 | D16: =C16*'FX & Assumptions'!$B$40 -> 189.21769 | E16: =D16-B16 -> 89.217687 | F16: =IF($B$8=0,0,B16/$B$8) -> 0.01263443 | G16: Essential | H16: Medical and family support transfers.
A17: SUBTOTAL ESSENTIAL | B17: =SUM(B12:B16) -> 6444.8767 | C17: =SUM(C12:C16) -> 1638.95 | D17: =SUM(D12:D16) -> 2169.1147 | E17: =SUM(E12:E16) -> -4275.762 | F17: =IF($B$8=0,0,B17/$B$8) -> 0.81427345 | G17: Critical | H17: This subtotal is the base of the emergency-fund target on the Goals sheet.
A19: LIFESTYLE — THE PART THAT IS ACTUALLY A CHOICE
A20: Line | B20: Monthly plan | C20: Ledger actual 3–25 Aug | D20: Monthly run rate | E20: Variance vs plan | F20: % of income | G20: Priority | H20: Note
A21: Dining | B21: 200 | C21: =SUMIFS('Recent Ledger'!$D$6:$D$101,'Recent Ledger'!$I$6:$I$101,$A21,'Recent Ledger'!$J$6:$J$101,1) -> 785.28 | D21: =C21*'FX & Assumptions'!$B$40 -> 1039.301 | E21: =D21-B21 -> 839.30101 | F21: =IF($B$8=0,0,B21/$B$8) -> 0.025268861 | G21: Discretionary | H21: The single largest controllable category in the ledger. Restaurant and delivery spending has been running far above any plan that also funds rent.
A22: Lifestyle & Shopping | B22: 100 | C22: =SUMIFS('Recent Ledger'!$D$6:$D$101,'Recent Ledger'!$I$6:$I$101,$A22,'Recent Ledger'!$J$6:$J$101,1) -> 563.75 | D22: =C22*'FX & Assumptions'!$B$40 -> 746.11087 | E22: =D22-B22 -> 646.11087 | F22: =IF($B$8=0,0,B22/$B$8) -> 0.01263443 | G22: Discretionary | H22: Convenience-store and hotel spending. Frozen under the damage-control cap.
A23: Grooming | B23: 65 | C23: =SUMIFS('Recent Ledger'!$D$6:$D$101,'Recent Ledger'!$I$6:$I$101,$A23,'Recent Ledger'!$J$6:$J$101,1) -> 65 | D23: =C23*'FX & Assumptions'!$B$40 -> 86.026087 | E23: =D23-B23 -> 21.026087 | F23: =IF($B$8=0,0,B23/$B$8) -> 0.0082123797 | G23: Discretionary | H23: One barber visit a month.
A24: Travel | B24: 0 | C24: =SUMIFS('Recent Ledger'!$D$6:$D$101,'Recent Ledger'!$I$6:$I$101,$A24,'Recent Ledger'!$J$6:$J$101,1) -> 1430 | D24: =C24*'FX & Assumptions'!$B$40 -> 1892.5739 | E24: =D24-B24 -> 1892.5739 | F24: =IF($B$8=0,0,B24/$B$8) -> 0 | G24: Deferred | H24: The AED 1,430 Emirates ticket sits in the ledger with a refund pending. No further travel spend is planned before the October rent cheque clears.
A25: Bank Fees | B25: 10 | C25: =SUMIFS('Recent Ledger'!$D$6:$D$101,'Recent Ledger'!$I$6:$I$101,$A25,'Recent Ledger'!$J$6:$J$101,1) -> 0.49 | D25: =C25*'FX & Assumptions'!$B$40 -> 0.64850435 | E25: =D25-B25 -> -9.3514957 | F25: =IF($B$8=0,0,B25/$B$8) -> 0.001263443 | G25: Avoidable | H25: Transfer fees. Avoidable with a little batching.
A26: Unreconciled | B26: 0 | C26: =SUMIFS('Recent Ledger'!$D$6:$D$101,'Recent Ledger'!$I$6:$I$101,$A26,'Recent Ledger'!$J$6:$J$101,1) -> 64 | D26: =C26*'FX & Assumptions'!$B$40 -> 84.702609 | E26: =D26-B26 -> 84.702609 | F26: =IF($B$8=0,0,B26/$B$8) -> 0 | G26: Control | H26: Balance-derived movements with no confirmed merchant. Target is zero: every dirham should have a name.
A27: SUBTOTAL LIFESTYLE | B27: =SUM(B21:B26) -> 375 | C27: =SUM(C21:C26) -> 2908.52 | D27: =SUM(D21:D26) -> 3849.363 | E27: =SUM(E21:E26) -> 3474.363 | F27: =IF($B$8=0,0,B27/$B$8) -> 0.047379114 | G27: Discretionary | H27: Every dirham cut here is a dirham that can fund rent, kill Tabby or buy units.
A29: DEBT AND WEALTH — WHAT BUILDS THE FUTURE
A30: Line | B30: Monthly plan | C30: Ledger actual 3–25 Aug | D30: Monthly run rate | E30: Variance vs plan | F30: % of income | G30: Priority | H30: Note
A31: Tabby repayment | B31: ='Inputs'!B36 -> 1314.5 | C31: 0 | D31: =C31*'FX & Assumptions'!$B$40 -> 0 | E31: =D31-B31 -> -1314.5 | F31: =IF($B$8=0,0,B31/$B$8) -> 0.16607959 | G31: Critical | H31: The no-fee minimum due 3 Sep. Paying the full statement is better whenever rent and essential bills stay funded.
A32: Nippon SIP | B32: ='FX & Assumptions'!B31 -> 462.4 | C32: 0 | D32: =C32*'FX & Assumptions'!$B$40 -> 0 | E32: =D32-B32 -> -462.4 | F32: =IF($B$8=0,0,B32/$B$8) -> 0.058421606 | G32: Wealth | H32: INR 12,000 a month. This is the only line in the budget that compounds.
A33: Emergency fund top-up | B33: 200 | C33: 0 | D33: =C33*'FX & Assumptions'!$B$40 -> 0 | E33: =D33-B33 -> -200 | F33: =IF($B$8=0,0,B33/$B$8) -> 0.025268861 | G33: Wealth | H33: The emergency fund holds AED 7.67 against a six-month target. AED 200 a month is the smallest amount that makes the number move.
A34: SUBTOTAL DEBT AND WEALTH | B34: =SUM(B31:B33) -> 1976.9 | C34: =SUM(C31:C33) -> 0 | D34: =SUM(D31:D33) -> 0 | E34: =SUM(E31:E33) -> -1976.9 | F34: =IF($B$8=0,0,B34/$B$8) -> 0.24977005 | G34: Wealth | H34: Debt repayment is defence; the SIP and the emergency fund are offence.
A36: RESULT
A37: Result | B37: Monthly plan | C37: Ledger actual 3–25 Aug | D37: Monthly run rate | E37: Variance vs plan | F37: % of income | G37: Verdict | H37: Note
A38: Total outflow | B38: =B17+B27+B34 -> 8796.7767 | C38: =C17+C27+C34 -> 4547.47 | D38: =D17+D27+D34 -> 6018.4777 | E38: =D38-B38 -> -2778.299 | F38: =IF($B$8=0,0,B38/$B$8) -> 1.1114226 | G38: =IF(B39>=0,"Plan balances","Plan does not balance") -> Plan does not balance | H38: Every planned dirham out, including debt repayment and investing.
A39: Surplus / (deficit) | B39: =B8-B38 -> -881.89667 | C39: =C8-C38 -> -4547.47 | D39: =D8-D38 -> -6018.4777 | E39: =D39-B39 -> -5136.581 | F39: =IF($B$8=0,0,B39/$B$8) -> -0.11142262 | G39: =IF(B39>=0,"OK","ACTION") -> ACTION | H39: Negative means the plan spends more than the salary. The gap has to be closed by cutting lifestyle, cutting a telecom line, or earning more — not by borrowing.
A40: BUDGET HEALTH RATIOS
A41: Ratio | B41: Value | C41: Benchmark | D41: Verdict | H41: Note
A42: Savings rate achieved | B42: =IF(B8=0,0,(B32+B33)/B8) -> 0.083690467 | C42: ='FX & Assumptions'!B30 -> 0.2 | D42: =IF(B42>=C42,"ON TARGET","BELOW TARGET") -> BELOW TARGET | H42: Investing plus emergency-fund top-ups as a share of net income, against the target lever.
A43: Essential ratio | B43: =IF(B8=0,0,B17/B8) -> 0.81427345 | C43: 0.5 | D43: =IF(B43<=C43,"OK","HIGH") -> HIGH | H43: Essentials above half of net income leaves almost no room to build wealth. Rent accrual is the dominant term.
A44: Lifestyle ratio | B44: =IF(B8=0,0,B27/B8) -> 0.047379114 | C44: 0.15 | D44: =IF(B44<=C44,"OK","HIGH") -> OK | H44: Discretionary spending as a share of net income.
A45: Run-rate lifestyle ratio (actual) | B45: =IF(B8=0,0,D27/B8) -> 0.48634509 | C45: 0.15 | D45: =IF(B45<=C45,"OK","HIGH") -> HIGH | H45: The same ratio measured on what the ledger actually shows, not on the plan. This is the honest number.
A47: How to use this sheet: fix column B once a month, then let column C fill itself from the ledger. The only line that must never be cut is the rent accrual — everything else is negotiable, and the Budget only balances once the negotiation actually happens.

Sheet Spend Analysis
A1: Where the Money Actually Went
A3: Built entirely from the confirmed ledger, 3–25 Aug 2026. Transfers between own accounts, salary credits and fully refunded charges are excluded, so nothing is counted twice and nothing is counted that never left.
A5: SPENDING BY CATEGORY
A6: Category | B6: Total | C6: Share | D6: Personal | E6: Household | F6: Per day | G6: Read
A7: Travel | B7: =SUMIFS('Recent Ledger'!$D$6:$D$101,'Recent Ledger'!$I$6:$I$101,$A7,'Recent Ledger'!$J$6:$J$101,1) -> 1430 | C7: =IF($B$17=0,0,B7/$B$17) -> 0.31446057 | D7: =SUMIFS('Recent Ledger'!$D$6:$D$101,'Recent Ledger'!$I$6:$I$101,$A7,'Recent Ledger'!$J$6:$J$101,1,'Recent Ledger'!$K$6:$K$101,"Personal") -> 0 | E7: =SUMIFS('Recent Ledger'!$D$6:$D$101,'Recent Ledger'!$I$6:$I$101,$A7,'Recent Ledger'!$J$6:$J$101,1,'Recent Ledger'!$K$6:$K$101,"Household") -> 1430 | F7: =IF('FX & Assumptions'!$B$39=0,0,B7/'FX & Assumptions'!$B$39) -> 62.173913 | G7: One Emirates ticket with a refund pending. Strip it out and the underlying burn rate is far lower — but the cash still left the account.
A8: Utilities & Telecom | B8: =SUMIFS('Recent Ledger'!$D$6:$D$101,'Recent Ledger'!$I$6:$I$101,$A8,'Recent Ledger'!$J$6:$J$101,1) -> 914.93 | C8: =IF($B$17=0,0,B8/$B$17) -> 0.20119539 | D8: =SUMIFS('Recent Ledger'!$D$6:$D$101,'Recent Ledger'!$I$6:$I$101,$A8,'Recent Ledger'!$J$6:$J$101,1,'Recent Ledger'!$K$6:$K$101,"Personal") -> 0 | E8: =SUMIFS('Recent Ledger'!$D$6:$D$101,'Recent Ledger'!$I$6:$I$101,$A8,'Recent Ledger'!$J$6:$J$101,1,'Recent Ledger'!$K$6:$K$101,"Household") -> 914.93 | F8: =IF('FX & Assumptions'!$B$39=0,0,B8/'FX & Assumptions'!$B$39) -> 39.779565 | G8: A single DubaiPay payment covering du and Etisalat. Two telecom contracts for one person is a standing, cancellable cost.
A9: Dining | B9: =SUMIFS('Recent Ledger'!$D$6:$D$101,'Recent Ledger'!$I$6:$I$101,$A9,'Recent Ledger'!$J$6:$J$101,1) -> 785.28 | C9: =IF($B$17=0,0,B9/$B$17) -> 0.17268503 | D9: =SUMIFS('Recent Ledger'!$D$6:$D$101,'Recent Ledger'!$I$6:$I$101,$A9,'Recent Ledger'!$J$6:$J$101,1,'Recent Ledger'!$K$6:$K$101,"Personal") -> 478.76 | E9: =SUMIFS('Recent Ledger'!$D$6:$D$101,'Recent Ledger'!$I$6:$I$101,$A9,'Recent Ledger'!$J$6:$J$101,1,'Recent Ledger'!$K$6:$K$101,"Household") -> 306.52 | F9: =IF('FX & Assumptions'!$B$39=0,0,B9/'FX & Assumptions'!$B$39) -> 34.142609 | G9: Restaurants, delivery and cafés. The largest genuinely controllable number in the file and the fastest route to closing the September gap.
A10: Lifestyle & Shopping | B10: =SUMIFS('Recent Ledger'!$D$6:$D$101,'Recent Ledger'!$I$6:$I$101,$A10,'Recent Ledger'!$J$6:$J$101,1) -> 563.75 | C10: =IF($B$17=0,0,B10/$B$17) -> 0.12397003 | D10: =SUMIFS('Recent Ledger'!$D$6:$D$101,'Recent Ledger'!$I$6:$I$101,$A10,'Recent Ledger'!$J$6:$J$101,1,'Recent Ledger'!$K$6:$K$101,"Personal") -> 563.75 | E10: =SUMIFS('Recent Ledger'!$D$6:$D$101,'Recent Ledger'!$I$6:$I$101,$A10,'Recent Ledger'!$J$6:$J$101,1,'Recent Ledger'!$K$6:$K$101,"Household") -> 0 | F10: =IF('FX & Assumptions'!$B$39=0,0,B10/'FX & Assumptions'!$B$39) -> 24.51087 | G10: Convenience stores and hotel bills. Small tickets, high frequency.
A11: Fuel & Transport | B11: =SUMIFS('Recent Ledger'!$D$6:$D$101,'Recent Ledger'!$I$6:$I$101,$A11,'Recent Ledger'!$J$6:$J$101,1) -> 300.52 | C11: =IF($B$17=0,0,B11/$B$17) -> 0.066085098 | D11: =SUMIFS('Recent Ledger'!$D$6:$D$101,'Recent Ledger'!$I$6:$I$101,$A11,'Recent Ledger'!$J$6:$J$101,1,'Recent Ledger'!$K$6:$K$101,"Personal") -> 180.52 | E11: =SUMIFS('Recent Ledger'!$D$6:$D$101,'Recent Ledger'!$I$6:$I$101,$A11,'Recent Ledger'!$J$6:$J$101,1,'Recent Ledger'!$K$6:$K$101,"Household") -> 120 | F11: =IF('FX & Assumptions'!$B$39=0,0,B11/'FX & Assumptions'!$B$39) -> 13.066087 | G11: Fuel and Metro. Work-essential; cut this last.
A12: Groceries | B12: =SUMIFS('Recent Ledger'!$D$6:$D$101,'Recent Ledger'!$I$6:$I$101,$A12,'Recent Ledger'!$J$6:$J$101,1) -> 280.53 | C12: =IF($B$17=0,0,B12/$B$17) -> 0.061689247 | D12: =SUMIFS('Recent Ledger'!$D$6:$D$101,'Recent Ledger'!$I$6:$I$101,$A12,'Recent Ledger'!$J$6:$J$101,1,'Recent Ledger'!$K$6:$K$101,"Personal") -> 181.78 | E12: =SUMIFS('Recent Ledger'!$D$6:$D$101,'Recent Ledger'!$I$6:$I$101,$A12,'Recent Ledger'!$J$6:$J$101,1,'Recent Ledger'!$K$6:$K$101,"Household") -> 98.75 | F12: =IF('FX & Assumptions'!$B$39=0,0,B12/'FX & Assumptions'!$B$39) -> 12.196957 | G12: Many small top-up trips rather than one weekly shop, which reliably costs more.
A13: Family & Support | B13: =SUMIFS('Recent Ledger'!$D$6:$D$101,'Recent Ledger'!$I$6:$I$101,$A13,'Recent Ledger'!$J$6:$J$101,1) -> 142.97 | C13: =IF($B$17=0,0,B13/$B$17) -> 0.03143946 | D13: =SUMIFS('Recent Ledger'!$D$6:$D$101,'Recent Ledger'!$I$6:$I$101,$A13,'Recent Ledger'!$J$6:$J$101,1,'Recent Ledger'!$K$6:$K$101,"Personal") -> 0 | E13: =SUMIFS('Recent Ledger'!$D$6:$D$101,'Recent Ledger'!$I$6:$I$101,$A13,'Recent Ledger'!$J$6:$J$101,1,'Recent Ledger'!$K$6:$K$101,"Household") -> 142.97 | F13: =IF('FX & Assumptions'!$B$39=0,0,B13/'FX & Assumptions'!$B$39) -> 6.216087 | G13: Medical support transfer. The duplicate was refunded and is excluded.
A14: Grooming | B14: =SUMIFS('Recent Ledger'!$D$6:$D$101,'Recent Ledger'!$I$6:$I$101,$A14,'Recent Ledger'!$J$6:$J$101,1) -> 65 | C14: =IF($B$17=0,0,B14/$B$17) -> 0.014293662 | D14: =SUMIFS('Recent Ledger'!$D$6:$D$101,'Recent Ledger'!$I$6:$I$101,$A14,'Recent Ledger'!$J$6:$J$101,1,'Recent Ledger'!$K$6:$K$101,"Personal") -> 65 | E14: =SUMIFS('Recent Ledger'!$D$6:$D$101,'Recent Ledger'!$I$6:$I$101,$A14,'Recent Ledger'!$J$6:$J$101,1,'Recent Ledger'!$K$6:$K$101,"Household") -> 0 | F14: =IF('FX & Assumptions'!$B$39=0,0,B14/'FX & Assumptions'!$B$39) -> 2.826087 | G14: One barber visit.
A15: Unreconciled | B15: =SUMIFS('Recent Ledger'!$D$6:$D$101,'Recent Ledger'!$I$6:$I$101,$A15,'Recent Ledger'!$J$6:$J$101,1) -> 64 | C15: =IF($B$17=0,0,B15/$B$17) -> 0.01407376 | D15: =SUMIFS('Recent Ledger'!$D$6:$D$101,'Recent Ledger'!$I$6:$I$101,$A15,'Recent Ledger'!$J$6:$J$101,1,'Recent Ledger'!$K$6:$K$101,"Personal") -> 0 | E15: =SUMIFS('Recent Ledger'!$D$6:$D$101,'Recent Ledger'!$I$6:$I$101,$A15,'Recent Ledger'!$J$6:$J$101,1,'Recent Ledger'!$K$6:$K$101,"Household") -> 64 | F15: =IF('FX & Assumptions'!$B$39=0,0,B15/'FX & Assumptions'!$B$39) -> 2.7826087 | G15: Movements proven by the balance trail but with no confirmed merchant, plus one outbound transfer to an untracked account. Target: zero.
A16: Bank Fees | B16: =SUMIFS('Recent Ledger'!$D$6:$D$101,'Recent Ledger'!$I$6:$I$101,$A16,'Recent Ledger'!$J$6:$J$101,1) -> 0.49 | C16: =IF($B$17=0,0,B16/$B$17) -> 0.0001077522 | D16: =SUMIFS('Recent Ledger'!$D$6:$D$101,'Recent Ledger'!$I$6:$I$101,$A16,'Recent Ledger'!$J$6:$J$101,1,'Recent Ledger'!$K$6:$K$101,"Personal") -> 0.49 | E16: =SUMIFS('Recent Ledger'!$D$6:$D$101,'Recent Ledger'!$I$6:$I$101,$A16,'Recent Ledger'!$J$6:$J$101,1,'Recent Ledger'!$K$6:$K$101,"Household") -> 0 | F16: =IF('FX & Assumptions'!$B$39=0,0,B16/'FX & Assumptions'!$B$39) -> 0.021304348 | G16: Transfer fee. Small, but pure leakage.
A17: TOTAL CONFIRMED SPENDING | B17: =SUM(B7:B16) -> 4547.47 | C17: =IF(B17=0,0,B17/B17) -> 1 | D17: =SUM(D7:D16) -> 1470.3 | E17: =SUM(E7:E16) -> 3077.17 | F17: =IF('FX & Assumptions'!$B$39=0,0,B17/'FX & Assumptions'!$B$39) -> 197.71609 | G17: Cross-check: this total must equal the sum of the 1-flagged rows in the ledger. The Checks sheet proves it.
A19: TOP MERCHANTS BY VALUE
A20: Merchant | B20: Total | C20: Share of spend | D20: Times seen | E20: Average ticket | F20: Per day | G20: Read
A21: Emirates ticket | B21: =SUMIFS('Recent Ledger'!$D$6:$D$101,'Recent Ledger'!$C$6:$C$101,$A21,'Recent Ledger'!$J$6:$J$101,1) -> 1430 | C21: =IF($B$17=0,0,B21/$B$17) -> 0.31446057 | D21: =COUNTIFS('Recent Ledger'!$C$6:$C$101,$A21,'Recent Ledger'!$J$6:$J$101,1) -> 1 | E21: =IF(D21=0,0,B21/D21) -> 1430 | F21: =IF('FX & Assumptions'!$B$39=0,0,B21/'FX & Assumptions'!$B$39) -> 62.173913 | G21: Single largest line in the ledger; refund pending.
A22: du + Etisalat via DubaiPay | B22: =SUMIFS('Recent Ledger'!$D$6:$D$101,'Recent Ledger'!$C$6:$C$101,$A22,'Recent Ledger'!$J$6:$J$101,1) -> 914.93 | C22: =IF($B$17=0,0,B22/$B$17) -> 0.20119539 | D22: =COUNTIFS('Recent Ledger'!$C$6:$C$101,$A22,'Recent Ledger'!$J$6:$J$101,1) -> 1 | E22: =IF(D22=0,0,B22/D22) -> 914.93 | F22: =IF('FX & Assumptions'!$B$39=0,0,B22/'FX & Assumptions'!$B$39) -> 39.779565 | G22: One payment, two contracts. Consolidating to one line is a permanent saving.
A23: RTS Business Bay Hotel | B23: =SUMIFS('Recent Ledger'!$D$6:$D$101,'Recent Ledger'!$C$6:$C$101,$A23,'Recent Ledger'!$J$6:$J$101,1) -> 386.75 | C23: =IF($B$17=0,0,B23/$B$17) -> 0.08504729 | D23: =COUNTIFS('Recent Ledger'!$C$6:$C$101,$A23,'Recent Ledger'!$J$6:$J$101,1) -> 3 | E23: =IF(D23=0,0,B23/D23) -> 128.91667 | F23: =IF('FX & Assumptions'!$B$39=0,0,B23/'FX & Assumptions'!$B$39) -> 16.815217 | G23: Three charges in one day. The kind of spend that only shows up when it is totalled.
A24: Asas Al Madina General | B24: =SUMIFS('Recent Ledger'!$D$6:$D$101,'Recent Ledger'!$C$6:$C$101,$A24,'Recent Ledger'!$J$6:$J$101,1) -> 338.3 | C24: =IF($B$17=0,0,B24/$B$17) -> 0.074393014 | D24: =COUNTIFS('Recent Ledger'!$C$6:$C$101,$A24,'Recent Ledger'!$J$6:$J$101,1) -> 20 | E24: =IF(D24=0,0,B24/D24) -> 16.915 | F24: =IF('FX & Assumptions'!$B$39=0,0,B24/'FX & Assumptions'!$B$39) -> 14.708696 | G24: The most frequent merchant in the file. Small tickets, constant repetition.
A25: 25 Hours F and B | B25: =SUMIFS('Recent Ledger'!$D$6:$D$101,'Recent Ledger'!$C$6:$C$101,$A25,'Recent Ledger'!$J$6:$J$101,1) -> 163.75 | C25: =IF($B$17=0,0,B25/$B$17) -> 0.036009034 | D25: =COUNTIFS('Recent Ledger'!$C$6:$C$101,$A25,'Recent Ledger'!$J$6:$J$101,1) -> 2 | E25: =IF(D25=0,0,B25/D25) -> 81.875 | F25: =IF('FX & Assumptions'!$B$39=0,0,B25/'FX & Assumptions'!$B$39) -> 7.1195652
A26: Emarat 1691 Mutina S | B26: =SUMIFS('Recent Ledger'!$D$6:$D$101,'Recent Ledger'!$C$6:$C$101,$A26,'Recent Ledger'!$J$6:$J$101,1) -> 120.02 | C26: =IF($B$17=0,0,B26/$B$17) -> 0.026392697 | D26: =COUNTIFS('Recent Ledger'!$C$6:$C$101,$A26,'Recent Ledger'!$J$6:$J$101,1) -> 1 | E26: =IF(D26=0,0,B26/D26) -> 120.02 | F26: =IF('FX & Assumptions'!$B$39=0,0,B26/'FX & Assumptions'!$B$39) -> 5.2182609
A27: Salkara / Team Taste | B27: =SUMIFS('Recent Ledger'!$D$6:$D$101,'Recent Ledger'!$C$6:$C$101,$A27,'Recent Ledger'!$J$6:$J$101,1) -> 101.5 | C27: =IF($B$17=0,0,B27/$B$17) -> 0.022320103 | D27: =COUNTIFS('Recent Ledger'!$C$6:$C$101,$A27,'Recent Ledger'!$J$6:$J$101,1) -> 1 | E27: =IF(D27=0,0,B27/D27) -> 101.5 | F27: =IF('FX & Assumptions'!$B$39=0,0,B27/'FX & Assumptions'!$B$39) -> 4.4130435
A28: e& Money medical support | B28: =SUMIFS('Recent Ledger'!$D$6:$D$101,'Recent Ledger'!$C$6:$C$101,$A28,'Recent Ledger'!$J$6:$J$101,1) -> 100 | C28: =IF($B$17=0,0,B28/$B$17) -> 0.021990249 | D28: =COUNTIFS('Recent Ledger'!$C$6:$C$101,$A28,'Recent Ledger'!$J$6:$J$101,1) -> 1 | E28: =IF(D28=0,0,B28/D28) -> 100 | F28: =IF('FX & Assumptions'!$B$39=0,0,B28/'FX & Assumptions'!$B$39) -> 4.3478261
A29: Cielo Kabab Restaurant | B29: =SUMIFS('Recent Ledger'!$D$6:$D$101,'Recent Ledger'!$C$6:$C$101,$A29,'Recent Ledger'!$J$6:$J$101,1) -> 78 | C29: =IF($B$17=0,0,B29/$B$17) -> 0.017152395 | D29: =COUNTIFS('Recent Ledger'!$C$6:$C$101,$A29,'Recent Ledger'!$J$6:$J$101,1) -> 1 | E29: =IF(D29=0,0,B29/D29) -> 78 | F29: =IF('FX & Assumptions'!$B$39=0,0,B29/'FX & Assumptions'!$B$39) -> 3.3913043
A30: Zomato | B30: =SUMIFS('Recent Ledger'!$D$6:$D$101,'Recent Ledger'!$C$6:$C$101,$A30,'Recent Ledger'!$J$6:$J$101,1) -> 66.52 | C30: =IF($B$17=0,0,B30/$B$17) -> 0.014627914 | D30: =COUNTIFS('Recent Ledger'!$C$6:$C$101,$A30,'Recent Ledger'!$J$6:$J$101,1) -> 1 | E30: =IF(D30=0,0,B30/D30) -> 66.52 | F30: =IF('FX & Assumptions'!$B$39=0,0,B30/'FX & Assumptions'!$B$39) -> 2.8921739
A31: ISK Gents Saloon | B31: =SUMIFS('Recent Ledger'!$D$6:$D$101,'Recent Ledger'!$C$6:$C$101,$A31,'Recent Ledger'!$J$6:$J$101,1) -> 65 | C31: =IF($B$17=0,0,B31/$B$17) -> 0.014293662 | D31: =COUNTIFS('Recent Ledger'!$C$6:$C$101,$A31,'Recent Ledger'!$J$6:$J$101,1) -> 1 | E31: =IF(D31=0,0,B31/D31) -> 65 | F31: =IF('FX & Assumptions'!$B$39=0,0,B31/'FX & Assumptions'!$B$39) -> 2.826087
A32: Sahil Zam Zam Mandi | B32: =SUMIFS('Recent Ledger'!$D$6:$D$101,'Recent Ledger'!$C$6:$C$101,$A32,'Recent Ledger'!$J$6:$J$101,1) -> 52 | C32: =IF($B$17=0,0,B32/$B$17) -> 0.01143493 | D32: =COUNTIFS('Recent Ledger'!$C$6:$C$101,$A32,'Recent Ledger'!$J$6:$J$101,1) -> 1 | E32: =IF(D32=0,0,B32/D32) -> 52 | F32: =IF('FX & Assumptions'!$B$39=0,0,B32/'FX & Assumptions'!$B$39) -> 2.2608696
A34: BURN RATE AND CONTROL
A35: Metric | B35: Value | C35: Benchmark | D35: Status | G35: Read
A36: Total spend in the ledger window | B36: =B17 -> 4547.47 | G36: Everything that genuinely left the accounts between 3 and 25 Aug.
A37: Spend excluding the refundable ticket | B37: =B17-B7 -> 3117.47 | G37: The underlying number once the one-off Emirates ticket is set aside.
A38: Spend excluding ticket and utilities | B38: =B17-B7-B8 -> 2202.54 | G38: Day-to-day living cost only: food, fuel, shops, grooming.
A39: Daily burn — day-to-day living | B39: =IF('FX & Assumptions'!$B$39=0,0,(B17-B7-B8)/'FX & Assumptions'!$B$39) -> 95.762609 | C39: ='Inputs'!B41/57 -> 5 | D39: =IF(B39<=C39,"WITHIN CAP","ABOVE CAP") -> ABOVE CAP | G39: This is the headline finding of the whole sheet. The damage-control plan caps living costs at AED 5 a day; the confirmed ledger shows a multiple of that. The cap is not being kept, and that gap is exactly why the rent cheque is at risk.
A40: Personal share of spending | B40: =IF(B17=0,0,D17/B17) -> 0.32332264 | C40: 0.35 | D40: =IF(B40<=C40,"OK","HIGH") -> OK | G40: Personal lifestyle spending against household and work-essential spending.
A41: Household share of spending | B41: =IF(B17=0,0,E17/B17) -> 0.67667736 | C41: 0.65 | G41: The balance of the split.
A42: Discretionary share (dining, lifestyle, grooming) | B42: =IF(B17=0,0,(B9+B10+B14)/B17) -> 0.31094873 | C42: 0.25 | D42: =IF(B42<=C42,"OK","HIGH") -> HIGH | G42: The share of spending that can be cut this week without any structural change.
A43: Monthly run rate at this pace | B43: =B17*'FX & Assumptions'!$B$40 -> 6018.4777 | C43: ='FX & Assumptions'!B25 -> 7914.88 | D43: =IF(B43<=C43,"WITHIN SALARY","ABOVE SALARY") -> WITHIN SALARY | G43: The partial ledger scaled to a full month, against net salary. If this reads ABOVE SALARY, the shortfall is structural, not bad luck.
A45: Read this sheet before the Budget. The Budget says what should happen; this sheet says what did. Where they disagree, this sheet is right.

Sheet Recent Ledger
A1: Recent Confirmed Ledger
A3: Personal and household transactions are separated; transfers and refunds never count as spending. Columns I to K normalise every line into one budget category, a 1/0 spend flag and a personal/household split so the Budget, Spend Analysis and AI Advisor sheets can total it without any manual sorting.
A5: Date/time | B5: Bank | C5: Merchant | D5: Amount | E5: Category | F5: Class | G5: Balance after | H5: Treatment | I5: Budget category | J5: Counts as spend | K5: Split
A6: 46237.472 | B6: FAB | C6: du + Etisalat via DubaiPay | D6: 914.93 | E6: Household utilities | F6: Household | G6: 2535.86 | H6: Expense · paid once | I6: Utilities & Telecom | J6: 1 | K6: Household
A7: 46237.5 | B7: NBD | C7: Asas Al Madina General | D7: 14 | E7: Lifestyle | F7: Personal | G7: 183.92 | H7: Expense | I7: Lifestyle & Shopping | J7: 1 | K7: Personal
A8: 46237.542 | B8: NBD | C8: Yas Home General Trading | D8: 22.97 | E8: Household other | F8: Household | G8: 160.95 | H8: Expense | I8: Family & Support | J8: 1 | K8: Household
A9: 46237.836 | B9: NBD | C9: Spicy Falcon Restaurant | D9: 16 | E9: Food & Dining | F9: Household | G9: 144.95 | H9: Expense | I9: Dining | J9: 1 | K9: Household
A10: 46238.196 | B10: NBD | C10: Emarat Nad Al Hamar | D10: 13.5 | E10: Lifestyle | F10: Personal | G10: 131.45 | H10: Expense | I10: Lifestyle & Shopping | J10: 1 | K10: Personal
A11: 46238.208 | B11: Tabby Cash | C11: Nad Al Hamar Star Grocery | D11: 2 | E11: Lifestyle | F11: Personal | G11: 0.89 | H11: Wallet expense; not Card debt | I11: Lifestyle & Shopping | J11: 1 | K11: Personal
A12: 46238.333 | B12: NBD | C12: Asas Al Madina General | D12: 24.5 | E12: Groceries | F12: Household | G12: 106.95 | H12: Expense | I12: Groceries | J12: 1 | K12: Household
A13: 46239.325 | B13: NBD | C13: Reel Entertainment | D13: 20 | E13: Household other | F13: Household | G13: 86.95 | H13: Expense | I13: Family & Support | J13: 1 | K13: Household
A14: 46239.449 | B14: NBD | C14: HNS Restaurant and Cafe | D14: 10 | E14: Food & Dining | F14: Household | G14: 76.95 | H14: Expense | I14: Dining | J14: 1 | K14: Household
A15: 46239.449 | B15: NBD | C15: Burger King Dubai Mall | D15: 10 | E15: Food & Dining | F15: Household | G15: 66.95 | H15: Expense | I15: Dining | J15: 1 | K15: Household
A16: 46239.45 | B16: NBD | C16: Texas Dubai Mall | D16: 10 | E16: Food & Dining | F16: Household | G16: 56.95 | H16: Expense | I16: Dining | J16: 1 | K16: Household
A17: 46239.64 | B17: NBD | C17: Team Taste Restaurant | D17: 31 | E17: Food & Dining | F17: Household | G17: 25.95 | H17: Expense | I17: Dining | J17: 1 | K17: Household
... A101: 46259.275 | B101: FAB 4001 | C101: ENOC Site 39 | D101: 13.5 | E101: Transport & Fuel | F101: Personal | G101: 3.45 | H101: Expense | I101: Fuel & Transport | J101: 1 | K101: Personal

Sheet Monthly Plan
A1: Cash Flow to the October Rent Cheque
A3: The model excludes the 26 Oct salary because the rent cheque clears on 22 Oct.
A5: Cash flow | B5: Aug 2026E | C5: Sep 2026E | D5: Oct 1–22E | E5: Total | F5: Status | G5: Notes
A6: Opening liquid cash | B6: ='Inputs'!B14 -> 6105.64 | C6: =B22 -> 8168.36 | D6: =C22 -> 12428.13 | E6: =SUM(B6:D6) -> 26702.13 | F6: Actual / last reported | G6: Reconciled 25 Aug from FAB app, NBD SMS and last-reported wallet balances
A7: Rent refund | B7: 0 | C7: 0 | D7: 0 | E7: 0 | F7: Actual received | G7: AED 1,430 is included in opening cash
